Workbook

Sheet INTRA LABORAL A
EO1: DIMENSION 1 | ES1: DIMENSION 2 | EX1: DIMENSION 3 | FF1: DIMENSION 4 | FH1: VALOR TOTAL POR DOMINIOS | FL1: TOTALES | FN1: DIMENSION 1 | FR1: DIMENSION 2 | FW1: DIMENSION 3 | GE1: DIMENSION 4 | GG1: DOMINIOS | GK1: TOTALES | GM1: Factores de Transformacion para el total de la evaluacion general de factores de riesgo psicosocial (Intra y Extra)
A2: FICHA DE DATOS GENERALES | V2: PREGUNTAS
EO3: LIDERERAZGO Y RELACIONES EN EL TRABAJO | ES3: CONTROL SOBRE EL TRABAJO | EX3: DEMANDAS DEL TRABAJO | FF3: RECOMPENSAS | FN3: LIDERERAZGO Y RELACIONES EN EL TRABAJO | FR3: CONTROL SOBRE EL TRABAJO | FW3: DEMANDAS DEL TRABAJO | GE3: RECOMPENSAS
A4: Item | B4: Nombre | C4: Identificacion | D4: Sexo | E4: Año Nacimiento | F4: Estado Civil | G4: Ultimo nivel de estudio | H4: Ocupacion/Profesion | I4: Lugar de Residencia | J4: Estrato | K4: Tipo de Vivienda | L4: Numero de personas a cargo | M4: Lugar donde trabaja actualmente | N4: Tiempo de trabajo en la empresa | O4: Cargo actual | P4: Seleccione el tipo de cargo | Q4: Hace cuantos años que desempeña el cargo u oficio en la empresa | R4: Nombre del area o seccion de la empresa en el que trabaja | S4: Tipo de contrato | T4: Horas diarias de trabajo al dia | U4: Tipo de salario que recibe | V4: 1 | W4: 2 | X4: 3 | Y4: 4 | Z4: 5 | AA4: 6 | AB4: 7 | AC4: 8 | AD4: 9 | AE4: 10 | AF4: 11 | AG4: 12 | AH4: 13 | AI4: 14 | AJ4: 15 | AK4: 16 | AL4: 17 | AM4: 18 | AN4: 19 | AO4: 20 | AP4: 21 | AQ4: 22 | AR4: 23 | AS4: 24 | AT4: 25 | AU4: 26 | AV4: 27 | AW4: 28 | AX4: 29 | AY4: 30 | AZ4: 31 | BA4: 32 | BB4: 33 | BC4: 34 | BD4: 35 | BE4: 36 | BF4: 37 | BG4: 38 | BH4: 39 | BI4: 40 | BJ4: 41 | BK4: 42 | BL4: 43 | BM4: 44 | BN4: 45 | BO4: 46 | BP4: 47 | BQ4: 48 | BR4: 49 | BS4: 50 | BT4: 51 | BU4: 52 | BV4: 53 | BW4: 54 | BX4: 55 | BY4: 56 | BZ4: 57 | CA4: 58 | CB4: 59 | CC4: 60 | CD4: 61 | CE4: 62 | CF4: 63 | CG4: 64 | CH4: 65 | CI4: 66 | CJ4: 67 | CK4: 68 | CL4: 69 | CM4: 70 | CN4: 71 | CO4: 72 | CP4: 73 | CQ4: 74 | CR4: 75 | CS4: 76 | CT4: 77 | CU4: 78 | CV4: 79 | CW4: 80 | CX4: 81 | CY4: 82 | CZ4: 83 | DA4: 84 | DB4: 85 | DC4: 86 | DD4: 87 | DE4: 88 | DF4: 89 | DG4: 90 | DH4: 91 | DI4: 92 | DJ4: 93 | DK4: 94 | DL4: 95 | DM4: 96 | DN4: 97 | DO4: 98 | DP4: 99 | DQ4: 100 | DR4: 101 | DS4: 102 | DT4: 103 | DU4: 104 | DV4: 105 | DW4: 106 | DX4: 107 | DY4: 108 | DZ4: 109 | EA4: 110 | EB4: 111 | EC4: 112 | ED4: 113 | EE4: 114 | EF4: 115 | EG4: 116 | EH4: 117 | EI4: 118 | EJ4: 119 | EK4: 120 | EL4: 121 | EM4: 122 | EN4: 123 | EO4: Caracteristicas del Liderazgo | EP4: Relaciones sociales en el trabajo | EQ4: Retroalimentacion del desempeño | ER4: Relacion con los colaboradores | ES4: Claridad del Rol | ET4: Capacitacion | EU4: Participacion y manejo del cambio | EV4: Oportunidades para el uso y desarrollo de habilidades y conocimientos | EW4: Control y autonomia sobre el trabajo | EX4: Demandas ambientales y de esfuerzo fisico | EY4: Demandas emocionales | EZ4: Demandas cualitativas | FA4: Influencia del trabajo sobre el entorno extralaboral | FB4: Exigencias de responsabilidad del cargo | FC4: Demandas de carga mental | FD4: Consistencia del Rol | FE4: Demandas de la jornada de trabajo | FF4: Recompensas derivadas de la pertenencia a la organización y del trabajo que se realiza | FG4: Reconocimientos y compensacion | FH4: LIDERAZGO Y RELACIONES SOCIALES EN EL TRABAJO | FI4: CONTROL SOBRE EL TRABAJO | FJ4: DEMANDAS DEL TRABAJO | FK4: RECOMPENSAS | FL4: Total General Factores de Riesgo Psicosocial Intralaboral | FN4: Caracteristicas del Liderazgo | FO4: Relaciones sociales en el trabajo | FP4: Retroalimentacion del desempeño | FQ4: Relacion con los colaboradores | FR4: Claridad del Rol | FS4: Capacitacion | FT4: Participacion y manejo del cambio | FU4: Oportunidades para el uso y desarrollo de habilidades y conocimientos | FV4: Control y autonomia sobre el trabajo | FW4: Demandas ambientales y de esfuerzo fisico | FX4: Demandas emocionales | FY4: Demandas cualitativas | FZ4: Influencia del trabajo sobre el entorno extralaboral | GA4: Exigencias de responsabilidad del cargo | GB4: Demandas de carga mental | GC4: Consistencia del Rol | GD4: Demandas de la jornada de trabajo | GE4: Recompensas derivadas de la pertenencia a la organización y del trabajo que se realiza | GF4: Reconocimientos y compensacion | GG4: LIDERAZGO Y RELACIONES SOCIALES EN EL TRABAJO | GH4: CONTROL SOBRE EL TRABAJO | GI4: DEMANDAS DEL TRABAJO | GJ4: RECOMPENSAS | GK4: Total General Factores de Riesgo Psicosocial Intralaboral | GM4: Sumatoria Intra - Extra Forma A | GN4: Puntaje Total de la Evaluacion General de factores de riesgo psicosocial (Suma intra + extra)
A5: 1 | B5: Adriana Katheribe Farfan | C5: 1075274331 | D5: f | E5: 1993 | F5: Casado | G5: Post-grado incompleto | H5: Ingeniero industrial | I5: Neiva | J5: 2 | K5: Propia | L5: 1 | M5: Neiva - Huila | N5: 3 años | O5: Administrdora | P5: Jefatura - tiene personal a cargo | Q5: 1 año | R5: Administración | S5: Temporal de menos de 1 año | T5: 8 | U5: Fijo | V5: 0 | W5: 0 | X5: 0 | Y5: 0 | Z5: 0 | AA5: 0 | AB5: 0 | AC5: 0 | AD5: 0 | AE5: 0 | AF5: 0 | AG5: 0 | AH5: 2 | AI5: 2 | AJ5: 2 | AK5: 3 | AL5: 4 | AM5: 3 | AN5: 2 | AO5: 2 | AP5: 2 | AQ5: 4 | AR5: 4 | AS5: 3 | AT5: 4 | AU5: 3 | AV5: 1 | AW5: 0 | AX5: 3 | AY5: 3 | AZ5: 4 | BA5: 1 | BB5: 1 | BC5: 4 | BD5: 0 | BE5: 0 | BF5: 2 | BG5: 1 | BH5: 0 | BI5: 0 | BJ5: 0 | BK5: 1 | BL5: 1 | BM5: 3 | BN5: 3 | BO5: 2 | BP5: 3 | BQ5: 2 | BR5: 0 | BS5: 1 | BT5: 1 | BU5: 1 | BV5: 1 | BW5: 1 | BX5: 1 | BY5: 0 | BZ5: 0 | CA5: 0 | CB5: 0 | CC5: 0 | CD5: 0 | CE5: 1 | CF5: 1 | CG5: 2 | CH5: 0 | CI5: 0 | CJ5: 3 | CK5: 1 | CL5: 1 | CM5: 0 | CN5: 1 | CO5: 0 | CP5: 0 | CQ5: 0 | CR5: 0 | CS5: 0 | CT5: 0 | CU5: 1 | CV5: 0 | CW5: 0 | CX5: 0 | CY5: 0 | CZ5: 1 | DA5: 0 | DB5: 0 | DC5: 0 | DD5: 1 | DE5: 0 | DF5: 0 | DG5: 2 | DH5: 1 | DI5: 1 | DJ5: 1 | DK5: 1 | DL5: 0 | DM5: 0 | DN5: 0 | DO5: 0 | DP5: 0 | DQ5: 0 | DR5: 0 | DS5: 0 | DT5: 0 | DU5: 0 | DV5: 0 | DW5: 1 | DX5: 2 | DY5: 1 | DZ5: 0 | EA5: 0 | EB5: 1 | EC5: 2 | ED5: 0 | EE5: 0 | EF5: 3 | EG5: 0 | EH5: 2 | EI5: 1 | EJ5: 1 | EK5: 0 | EL5: 0 | EM5: 2 | EN5: 0 | EO5: =+SUM(CF5:CR5) -> 9 | EP5: =+SUM(CS5:DF5) -> 3 | EQ5: =+SUM(DG5:DK5) -> 6 | ER5: =+SUM(EF5:EN5) -> 9 | ES5: =+SUM(BV5:CB5) -> 3 | ET5: =+SUM(CC5:CE5) -> 1 | EU5: =+SUM(BQ5:BT5) -> 4 | EV5: =+SUM(BH5:BK5) -> 1 | EW5: =+SUM(BM5:BO5) -> 8 | EX5: =+SUM(V5:AG5) -> 0 | EY5: =+SUM(DW5:EE5) -> 7 | EZ5: =+SUM(AH5+AI5+AJ5+BA5+BL5+BP5) -> 11 | FA5: =SUM(BD5:BG5) -> 3 | FB5: =+SUM(AN5+AQ5+AR5+AS5+AT5+AU5) -> 20 | FC5: =+SUM(AK5+AL5+AM5+AO5+AP5) -> 14 | FD5: =+SUM(AV5+AW5+AX5+AY5+BU5) -> 8 | FE5: =+SUM(AZ5+BB5+BC5) -> 9 | FF5: =+SUM(DL5+DS5+DT5+DU5+DV5) -> 0 | FG5: =+SUM(DM5:DR5) -> 0 | FH5: =+SUM(EO5:ER5) -> 27 | FI5: =+SUM(ES5:EW5) -> 17 | FJ5: =+SUM(EX5:FE5) -> 72 | FK5: =+SUM(FF5:FG5) -> 0 | FL5: =+SUM(FH5:FK5) -> 116 | FN5: =+SUM(EO5/52)*100 -> 17.307692 | FO5: =+SUM(EP5/56)*100 -> 5.3571429 | FP5: =+SUM(EQ5/20)*100 -> 30 | FQ5: =+SUM(ER5/36)*100 -> 25 | FR5: =+SUM(ES5/28)*100 -> 10.714286 | FS5: =+SUM(ET5/12)*100 -> 8.3333333 | FT5: =+SUM(EU5/16)*100 -> 25 | FU5: =+SUM(EV5/16)*100 -> 6.25 | FV5: =+SUM(EW5/12)*100 -> 66.666667 | FW5: =+SUM(EX5/48)*100 -> 0 | FX5: =+SUM(EY5/36)*100 -> 19.444444 | FY5: =+SUM(EZ5/24)*100 -> 45.833333 | FZ5: =+SUM(FA5/16)*100 -> 18.75 | GA5: =+SUM(FB5/24)*100 -> 83.333333 | GB5: =+SUM(FC5/20)*100 -> 70 | GC5: =+SUM(FD5/20)*100 -> 40 | GD5: =+SUM(FE5/12)*100 -> 75 | GE5: =+SUM(FF5/20)*100 -> 0 | GF5: =+SUM(FG5/24)*100 -> 0 | GG5: =+SUM(FH5/164)*100 -> 16.463415 | GH5: =+SUM(FI5/84)*100 -> 20.238095 | GI5: =+SUM(FJ5/200)*100 -> 36 | GJ5: =+SUM(FK5/44)*100 -> 0 | GK5: =+SUM(FL5/492)*100 -> 23.577236 | GM5: =FL5+'EXTRALABORAL A '!BH4 -> 143 | GN5: =+SUM(GM5/616)*100 -> 23.214286
A6: 2 | B6: Ever Adames Ramón | C6: 7696889 | D6: m | E6: 1974 | F6: Soltero (a) | G6: Post-grado completo | H6: Ingeniero | I6: Neiva | J6: 3 | K6: Propia | L6: 1 | M6: Neiva - Huila | N6: 20 años | O6: Gerente | P6: Jefatura - tiene personal a cargo | Q6: 10 años | R6: Gerencia | S6: Termino Indefinido | T6: 8 | U6: Una Parte fija y otra variable | V6: 0 | W6: 0 | X6: 0 | Y6: 0 | Z6: 0 | AA6: 0 | AB6: 0 | AC6: 0 | AD6: 0 | AE6: 1 | AF6: 1 | AG6: 4 | AH6: 0 | AI6: 0 | AJ6: 0 | AK6: 1 | AL6: 3 | AM6: 2 | AN6: 2 | AO6: 1 | AP6: 3 | AQ6: 1 | AR6: 3 | AS6: 3 | AT6: 4 | AU6: 2 | AV6: 0 | AW6: 0 | AX6: 0 | AY6: 0 | AZ6: 0 | BA6: 0 | BB6: 0 | BC6: 0 | BD6: 0 | BE6: 0 | BF6: 0 | BG6: 0 | BH6: 0 | BI6: 0 | BJ6: 0 | BK6: 0 | BL6: 0 | BM6: 0 | BN6: 0 | BO6: 0 | BP6: 0 | BQ6: 0 | BR6: 0 | BS6: 0 | BT6: 0 | BU6: 0 | BV6: 0 | BW6: 0 | BX6: 0 | BY6: 0 | BZ6: 0 | CA6: 0 | CB6: 0 | CC6: 0 | CD6: 0 | CE6: 0 | CF6: 0 | CG6: 0 | CH6: 0 | CI6: 0 | CJ6: 0 | CK6: 0 | CL6: 0 | CM6: 0 | CN6: 0 | CO6: 0 | CP6: 0 | CQ6: 0 | CR6: 0 | CS6: 0 | CT6: 0 | CU6: 0 | CV6: 0 | CW6: 0 | CX6: 0 | CY6: 0 | CZ6: 0 | DA6: 0 | DB6: 0 | DC6: 0 | DD6: 0 | DE6: 0 | DF6: 0 | DG6: 0 | DH6: 0 | DI6: 0 | DJ6: 0 | DK6: 0 | DL6: 0 | DM6: 0 | DN6: 0 | DO6: 0 | DP6: 0 | DQ6: 0 | DR6: 0 | DS6: 0 | DT6: 0 | DU6: 0 | DV6: 0 | DW6: 0 | DX6: 0 | DY6: 0 | DZ6: 0 | EA6: 0 | EB6: 0 | EC6: 0 | ED6: 0 | EE6: 0 | EF6: 0 | EG6: 0 | EH6: 0 | EI6: 0 | EJ6: 0 | EK6: 0 | EL6: 0 | EM6: 0 | EN6: 0 | EO6: =+SUM(CF6:CR6) -> 0 | EP6: =+SUM(CS6:DF6) -> 0 | EQ6: =+SUM(DG6:DK6) -> 0 | ER6: =+SUM(EF6:EN6) -> 0 | ES6: =+SUM(BV6:CB6) -> 0 | ET6: =+SUM(CC6:CE6) -> 0 | EU6: =+SUM(BQ6:BT6) -> 0 | EV6: =+SUM(BH6:BK6) -> 0 | EW6: =+SUM(BM6:BO6) -> 0 | EX6: =+SUM(V6:AG6) -> 6 | EY6: =+SUM(DW6:EE6) -> 0 | EZ6: =+SUM(AH6+AI6+AJ6+BA6+BL6+BP6) -> 0 | FA6: =SUM(BD6:BG6) -> 0 | FB6: =+SUM(AN6+AQ6+AR6+AS6+AT6+AU6) -> 15 | FC6: =+SUM(AK6+AL6+AM6+AO6+AP6) -> 10 | FD6: =+SUM(AV6+AW6+AX6+AY6+BU6) -> 0 | FE6: =+SUM(AZ6+BB6+BC6) -> 0 | FF6: =+SUM(DL6+DS6+DT6+DU6+DV6) -> 0 | FG6: =+SUM(DM6:DR6) -> 0 | FH6: =+SUM(EO6:ER6) -> 0 | FI6: =+SUM(ES6:EW6) -> 0 | FJ6: =+SUM(EX6:FE6) -> 31 | FK6: =+SUM(FF6:FG6) -> 0 | FL6: =+SUM(FH6:FK6) -> 31 | FN6: =+SUM(EO6/52)*100 -> 0 | FO6: =+SUM(EP6/56)*100 -> 0 | FP6: =+SUM(EQ6/20)*100 -> 0 | FQ6: =+SUM(ER6/36)*100 -> 0 | FR6: =+SUM(ES6/28)*100 -> 0 | FS6: =+SUM(ET6/12)*100 -> 0 | FT6: =+SUM(EU6/16)*100 -> 0 | FU6: =+SUM(EV6/16)*100 -> 0 | FV6: =+SUM(EW6/12)*100 -> 0 | FW6: =+SUM(EX6/48)*100 -> 12.5 | FX6: =+SUM(EY6/36)*100 -> 0 | FY6: =+SUM(EZ6/24)*100 -> 0 | FZ6: =+SUM(FA6/16)*100 -> 0 | GA6: =+SUM(FB6/24)*100 -> 62.5 | GB6: =+SUM(FC6/20)*100 -> 50 | GC6: =+SUM(FD6/20)*100 -> 0 | GD6: =+SUM(FE6/12)*100 -> 0 | GE6: =+SUM(FF6/20)*100 -> 0 | GF6: =+SUM(FG6/24)*100 -> 0 | GG6: =+SUM(FH6/164)*100 -> 0 | GH6: =+SUM(FI6/84)*100 -> 0 | GI6: =+SUM(FJ6/200)*100 -> 15.5 | GJ6: =+SUM(FK6/44)*100 -> 0 | GK6: =+SUM(FL6/492)*100 -> 6.300813 | GM6: =FL6+'EXTRALABORAL A '!BH5 -> 58 | GN6: =+SUM(GM6/616)*100 -> 9.4155844
A7: 3 | EO7: =+SUM(CF7:CR7) -> 0 | EP7: =+SUM(CS7:DF7) -> 0 | EQ7: =+SUM(DG7:DK7) -> 0 | ER7: =+SUM(EF7:EN7) -> 0 | ES7: =+SUM(BV7:CB7) -> 0 | ET7: =+SUM(CC7:CE7) -> 0 | EU7: =+SUM(BQ7:BT7) -> 0 | EV7: =+SUM(BH7:BK7) -> 0 | EW7: =+SUM(BM7:BO7) -> 0 | EX7: =+SUM(V7:AG7) -> 0 | EY7: =+SUM(DW7:EE7) -> 0 | EZ7: =+SUM(AH7+AI7+AJ7+BA7+BL7+BP7) -> 0 | FA7: =SUM(BD7:BG7) -> 0 | FB7: =+SUM(AN7+AQ7+AR7+AS7+AT7+AU7) -> 0 | FC7: =+SUM(AK7+AL7+AM7+AO7+AP7) -> 0 | FD7: =+SUM(AV7+AW7+AX7+AY7+BU7) -> 0 | FE7: =+SUM(AZ7+BB7+BC7) -> 0 | FF7: =+SUM(DL7+DS7+DT7+DU7+DV7) -> 0 | FG7: =+SUM(DM7:DR7) -> 0 | FH7: =+SUM(EO7:ER7) -> 0 | FI7: =+SUM(ES7:EW7) -> 0 | FJ7: =+SUM(EX7:FE7) -> 0 | FK7: =+SUM(FF7:FG7) -> 0 | FL7: =+SUM(FH7:FK7) -> 0 | FN7: =+SUM(EO7/52)*100 -> 0 | FO7: =+SUM(EP7/56)*100 -> 0 | FP7: =+SUM(EQ7/20)*100 -> 0 | FQ7: =+SUM(ER7/36)*100 -> 0 | FR7: =+SUM(ES7/28)*100 -> 0 | FS7: =+SUM(ET7/12)*100 -> 0 | FT7: =+SUM(EU7/16)*100 -> 0 | FU7: =+SUM(EV7/16)*100 -> 0 | FV7: =+SUM(EW7/12)*100 -> 0 | FW7: =+SUM(EX7/48)*100 -> 0 | FX7: =+SUM(EY7/36)*100 -> 0 | FY7: =+SUM(EZ7/24)*100 -> 0 | FZ7: =+SUM(FA7/16)*100 -> 0 | GA7: =+SUM(FB7/24)*100 -> 0 | GB7: =+SUM(FC7/20)*100 -> 0 | GC7: =+SUM(FD7/20)*100 -> 0 | GD7: =+SUM(FE7/12)*100 -> 0 | GE7: =+SUM(FF7/20)*100 -> 0 | GF7: =+SUM(FG7/24)*100 -> 0 | GG7: =+SUM(FH7/164)*100 -> 0 | GH7: =+SUM(FI7/84)*100 -> 0 | GI7: =+SUM(FJ7/200)*100 -> 0 | GJ7: =+SUM(FK7/44)*100 -> 0 | GK7: =+SUM(FL7/492)*100 -> 0 | GM7: =FL7+'EXTRALABORAL A '!BH6 -> 0 | GN7: =+SUM(GM7/616)*100 -> 0
A8: 4 | EO8: =+SUM(CF8:CR8) -> 0 | EP8: =+SUM(CS8:DF8) -> 0 | EQ8: =+SUM(DG8:DK8) -> 0 | ER8: =+SUM(EF8:EN8) -> 0 | ES8: =+SUM(BV8:CB8) -> 0 | ET8: =+SUM(CC8:CE8) -> 0 | EU8: =+SUM(BQ8:BT8) -> 0 | EV8: =+SUM(BH8:BK8) -> 0 | EW8: =+SUM(BM8:BO8) -> 0 | EX8: =+SUM(V8:AG8) -> 0 | EY8: =+SUM(DW8:EE8) -> 0 | EZ8: =+SUM(AH8+AI8+AJ8+BA8+BL8+BP8) -> 0 | FA8: =SUM(BD8:BG8) -> 0 | FB8: =+SUM(AN8+AQ8+AR8+AS8+AT8+AU8) -> 0 | FC8: =+SUM(AK8+AL8+AM8+AO8+AP8) -> 0 | FD8: =+SUM(AV8+AW8+AX8+AY8+BU8) -> 0 | FE8: =+SUM(AZ8+BB8+BC8) -> 0 | FF8: =+SUM(DL8+DS8+DT8+DU8+DV8) -> 0 | FG8: =+SUM(DM8:DR8) -> 0 | FH8: =+SUM(EO8:ER8) -> 0 | FI8: =+SUM(ES8:EW8) -> 0 | FJ8: =+SUM(EX8:FE8) -> 0 | FK8: =+SUM(FF8:FG8) -> 0 | FL8: =+SUM(FH8:FK8) -> 0 | FN8: =+SUM(EO8/52)*100 -> 0 | FO8: =+SUM(EP8/56)*100 -> 0 | FP8: =+SUM(EQ8/20)*100 -> 0 | FQ8: =+SUM(ER8/36)*100 -> 0 | FR8: =+SUM(ES8/28)*100 -> 0 | FS8: =+SUM(ET8/12)*100 -> 0 | FT8: =+SUM(EU8/16)*100 -> 0 | FU8: =+SUM(EV8/16)*100 -> 0 | FV8: =+SUM(EW8/12)*100 -> 0 | FW8: =+SUM(EX8/48)*100 -> 0 | FX8: =+SUM(EY8/36)*100 -> 0 | FY8: =+SUM(EZ8/24)*100 -> 0 | FZ8: =+SUM(FA8/16)*100 -> 0 | GA8: =+SUM(FB8/24)*100 -> 0 | GB8: =+SUM(FC8/20)*100 -> 0 | GC8: =+SUM(FD8/20)*100 -> 0 | GD8: =+SUM(FE8/12)*100 -> 0 | GE8: =+SUM(FF8/20)*100 -> 0 | GF8: =+SUM(FG8/24)*100 -> 0 | GG8: =+SUM(FH8/164)*100 -> 0 | GH8: =+SUM(FI8/84)*100 -> 0 | GI8: =+SUM(FJ8/200)*100 -> 0 | GJ8: =+SUM(FK8/44)*100 -> 0 | GK8: =+SUM(FL8/492)*100 -> 0 | GM8: =FL8+'EXTRALABORAL A '!BH7 -> 0 | GN8: =+SUM(GM8/616)*100 -> 0
A9: 5 | EO9: =+SUM(CF9:CR9) -> 0 | EP9: =+SUM(CS9:DF9) -> 0 | EQ9: =+SUM(DG9:DK9) -> 0 | ER9: =+SUM(EF9:EN9) -> 0 | ES9: =+SUM(BV9:CB9) -> 0 | ET9: =+SUM(CC9:CE9) -> 0 | EU9: =+SUM(BQ9:BT9) -> 0 | EV9: =+SUM(BH9:BK9) -> 0 | EW9: =+SUM(BM9:BO9) -> 0 | EX9: =+SUM(V9:AG9) -> 0 | EY9: =+SUM(DW9:EE9) -> 0 | EZ9: =+SUM(AH9+AI9+AJ9+BA9+BL9+BP9) -> 0 | FA9: =SUM(BD9:BG9) -> 0 | FB9: =+SUM(AN9+AQ9+AR9+AS9+AT9+AU9) -> 0 | FC9: =+SUM(AK9+AL9+AM9+AO9+AP9) -> 0 | FD9: =+SUM(AV9+AW9+AX9+AY9+BU9) -> 0 | FE9: =+SUM(AZ9+BB9+BC9) -> 0 | FF9: =+SUM(DL9+DS9+DT9+DU9+DV9) -> 0 | FG9: =+SUM(DM9:DR9) -> 0 | FH9: =+SUM(EO9:ER9) -> 0 | FI9: =+SUM(ES9:EW9) -> 0 | FJ9: =+SUM(EX9:FE9) -> 0 | FK9: =+SUM(FF9:FG9) -> 0 | FL9: =+SUM(FH9:FK9) -> 0 | FN9: =+SUM(EO9/52)*100 -> 0 | FO9: =+SUM(EP9/56)*100 -> 0 | FP9: =+SUM(EQ9/20)*100 -> 0 | FQ9: =+SUM(ER9/36)*100 -> 0 | FR9: =+SUM(ES9/28)*100 -> 0 | FS9: =+SUM(ET9/12)*100 -> 0 | FT9: =+SUM(EU9/16)*100 -> 0 | FU9: =+SUM(EV9/16)*100 -> 0 | FV9: =+SUM(EW9/12)*100 -> 0 | FW9: =+SUM(EX9/48)*100 -> 0 | FX9: =+SUM(EY9/36)*100 -> 0 | FY9: =+SUM(EZ9/24)*100 -> 0 | FZ9: =+SUM(FA9/16)*100 -> 0 | GA9: =+SUM(FB9/24)*100 -> 0 | GB9: =+SUM(FC9/20)*100 -> 0 | GC9: =+SUM(FD9/20)*100 -> 0 | GD9: =+SUM(FE9/12)*100 -> 0 | GE9: =+SUM(FF9/20)*100 -> 0 | GF9: =+SUM(FG9/24)*100 -> 0 | GG9: =+SUM(FH9/164)*100 -> 0 | GH9: =+SUM(FI9/84)*100 -> 0 | GI9: =+SUM(FJ9/200)*100 -> 0 | GJ9: =+SUM(FK9/44)*100 -> 0 | GK9: =+SUM(FL9/492)*100 -> 0 | GM9: =FL9+'EXTRALABORAL A '!BH8 -> 0 | GN9: =+SUM(GM9/616)*100 -> 0
A10: 6 | EO10: =+SUM(CF10:CR10) -> 0 | EP10: =+SUM(CS10:DF10) -> 0 | EQ10: =+SUM(DG10:DK10) -> 0 | ER10: =+SUM(EF10:EN10) -> 0 | ES10: =+SUM(BV10:CB10) -> 0 | ET10: =+SUM(CC10:CE10) -> 0 | EU10: =+SUM(BQ10:BT10) -> 0 | EV10: =+SUM(BH10:BK10) -> 0 | EW10: =+SUM(BM10:BO10) -> 0 | EX10: =+SUM(V10:AG10) -> 0 | EY10: =+SUM(DW10:EE10) -> 0 | EZ10: =+SUM(AH10+AI10+AJ10+BA10+BL10+BP10) -> 0 | FA10: =SUM(BD10:BG10) -> 0 | FB10: =+SUM(AN10+AQ10+AR10+AS10+AT10+AU10) -> 0 | FC10: =+SUM(AK10+AL10+AM10+AO10+AP10) -> 0 | FD10: =+SUM(AV10+AW10+AX10+AY10+BU10) -> 0 | FE10: =+SUM(AZ10+BB10+BC10) -> 0 | FF10: =+SUM(DL10+DS10+DT10+DU10+DV10) -> 0 | FG10: =+SUM(DM10:DR10) -> 0 | FH10: =+SUM(EO10:ER10) -> 0 | FI10: =+SUM(ES10:EW10) -> 0 | FJ10: =+SUM(EX10:FE10) -> 0 | FK10: =+SUM(FF10:FG10) -> 0 | FL10: =+SUM(FH10:FK10) -> 0 | FN10: =+SUM(EO10/52)*100 -> 0 | FO10: =+SUM(EP10/56)*100 -> 0 | FP10: =+SUM(EQ10/20)*100 -> 0 | FQ10: =+SUM(ER10/36)*100 -> 0 | FR10: =+SUM(ES10/28)*100 -> 0 | FS10: =+SUM(ET10/12)*100 -> 0 | FT10: =+SUM(EU10/16)*100 -> 0 | FU10: =+SUM(EV10/16)*100 -> 0 | FV10: =+SUM(EW10/12)*100 -> 0 | FW10: =+SUM(EX10/48)*100 -> 0 | FX10: =+SUM(EY10/36)*100 -> 0 | FY10: =+SUM(EZ10/24)*100 -> 0 | FZ10: =+SUM(FA10/16)*100 -> 0 | GA10: =+SUM(FB10/24)*100 -> 0 | GB10: =+SUM(FC10/20)*100 -> 0 | GC10: =+SUM(FD10/20)*100 -> 0 | GD10: =+SUM(FE10/12)*100 -> 0 | GE10: =+SUM(FF10/20)*100 -> 0 | GF10: =+SUM(FG10/24)*100 -> 0 | GG10: =+SUM(FH10/164)*100 -> 0 | GH10: =+SUM(FI10/84)*100 -> 0 | GI10: =+SUM(FJ10/200)*100 -> 0 | GJ10: =+SUM(FK10/44)*100 -> 0 | GK10: =+SUM(FL10/492)*100 -> 0 | GM10: =FL10+'EXTRALABORAL A '!BH9 -> 0 | GN10: =+SUM(GM10/616)*100 -> 0
A11: 7 | EO11: =+SUM(CF11:CR11) -> 0 | EP11: =+SUM(CS11:DF11) -> 0 | EQ11: =+SUM(DG11:DK11) -> 0 | ER11: =+SUM(EF11:EN11) -> 0 | ES11: =+SUM(BV11:CB11) -> 0 | ET11: =+SUM(CC11:CE11) -> 0 | EU11: =+SUM(BQ11:BT11) -> 0 | EV11: =+SUM(BH11:BK11) -> 0 | EW11: =+SUM(BM11:BO11) -> 0 | EX11: =+SUM(V11:AG11) -> 0 | EY11: =+SUM(DW11:EE11) -> 0 | EZ11: =+SUM(AH11+AI11+AJ11+BA11+BL11+BP11) -> 0 | FA11: =SUM(BD11:BG11) -> 0 | FB11: =+SUM(AN11+AQ11+AR11+AS11+AT11+AU11) -> 0 | FC11: =+SUM(AK11+AL11+AM11+AO11+AP11) -> 0 | FD11: =+SUM(AV11+AW11+AX11+AY11+BU11) -> 0 | FE11: =+SUM(AZ11+BB11+BC11) -> 0 | FF11: =+SUM(DL11+DS11+DT11+DU11+DV11) -> 0 | FG11: =+SUM(DM11:DR11) -> 0 | FH11: =+SUM(EO11:ER11) -> 0 | FI11: =+SUM(ES11:EW11) -> 0 | FJ11: =+SUM(EX11:FE11) -> 0 | FK11: =+SUM(FF11:FG11) -> 0 | FL11: =+SUM(FH11:FK11) -> 0 | FN11: =+SUM(EO11/52)*100 -> 0 | FO11: =+SUM(EP11/56)*100 -> 0 | FP11: =+SUM(EQ11/20)*100 -> 0 | FQ11: =+SUM(ER11/36)*100 -> 0 | FR11: =+SUM(ES11/28)*100 -> 0 | FS11: =+SUM(ET11/12)*100 -> 0 | FT11: =+SUM(EU11/16)*100 -> 0 | FU11: =+SUM(EV11/16)*100 -> 0 | FV11: =+SUM(EW11/12)*100 -> 0 | FW11: =+SUM(EX11/48)*100 -> 0 | FX11: =+SUM(EY11/36)*100 -> 0 | FY11: =+SUM(EZ11/24)*100 -> 0 | FZ11: =+SUM(FA11/16)*100 -> 0 | GA11: =+SUM(FB11/24)*100 -> 0 | GB11: =+SUM(FC11/20)*100 -> 0 | GC11: =+SUM(FD11/20)*100 -> 0 | GD11: =+SUM(FE11/12)*100 -> 0 | GE11: =+SUM(FF11/20)*100 -> 0 | GF11: =+SUM(FG11/24)*100 -> 0 | GG11: =+SUM(FH11/164)*100 -> 0 | GH11: =+SUM(FI11/84)*100 -> 0 | GI11: =+SUM(FJ11/200)*100 -> 0 | GJ11: =+SUM(FK11/44)*100 -> 0 | GK11: =+SUM(FL11/492)*100 -> 0 | GM11: =FL11+'EXTRALABORAL A '!BH10 -> 0 | GN11: =+SUM(GM11/616)*100 -> 0
A12: 8 | EO12: =+SUM(CF12:CR12) -> 0 | EP12: =+SUM(CS12:DF12) -> 0 | EQ12: =+SUM(DG12:DK12) -> 0 | ER12: =+SUM(EF12:EN12) -> 0 | ES12: =+SUM(BV12:CB12) -> 0 | ET12: =+SUM(CC12:CE12) -> 0 | EU12: =+SUM(BQ12:BT12) -> 0 | EV12: =+SUM(BH12:BK12) -> 0 | EW12: =+SUM(BM12:BO12) -> 0 | EX12: =+SUM(V12:AG12) -> 0 | EY12: =+SUM(DW12:EE12) -> 0 | EZ12: =+SUM(AH12+AI12+AJ12+BA12+BL12+BP12) -> 0 | FA12: =SUM(BD12:BG12) -> 0 | FB12: =+SUM(AN12+AQ12+AR12+AS12+AT12+AU12) -> 0 | FC12: =+SUM(AK12+AL12+AM12+AO12+AP12) -> 0 | FD12: =+SUM(AV12+AW12+AX12+AY12+BU12) -> 0 | FE12: =+SUM(AZ12+BB12+BC12) -> 0 | FF12: =+SUM(DL12+DS12+DT12+DU12+DV12) -> 0 | FG12: =+SUM(DM12:DR12) -> 0 | FH12: =+SUM(EO12:ER12) -> 0 | FI12: =+SUM(ES12:EW12) -> 0 | FJ12: =+SUM(EX12:FE12) -> 0 | FK12: =+SUM(FF12:FG12) -> 0 | FL12: =+SUM(FH12:FK12) -> 0 | FN12: =+SUM(EO12/52)*100 -> 0 | FO12: =+SUM(EP12/56)*100 -> 0 | FP12: =+SUM(EQ12/20)*100 -> 0 | FQ12: =+SUM(ER12/36)*100 -> 0 | FR12: =+SUM(ES12/28)*100 -> 0 | FS12: =+SUM(ET12/12)*100 -> 0 | FT12: =+SUM(EU12/16)*100 -> 0 | FU12: =+SUM(EV12/16)*100 -> 0 | FV12: =+SUM(EW12/12)*100 -> 0 | FW12: =+SUM(EX12/48)*100 -> 0 | FX12: =+SUM(EY12/36)*100 -> 0 | FY12: =+SUM(EZ12/24)*100 -> 0 | FZ12: =+SUM(FA12/16)*100 -> 0 | GA12: =+SUM(FB12/24)*100 -> 0 | GB12: =+SUM(FC12/20)*100 -> 0 | GC12: =+SUM(FD12/20)*100 -> 0 | GD12: =+SUM(FE12/12)*100 -> 0 | GE12: =+SUM(FF12/20)*100 -> 0 | GF12: =+SUM(FG12/24)*100 -> 0 | GG12: =+SUM(FH12/164)*100 -> 0 | GH12: =+SUM(FI12/84)*100 -> 0 | GI12: =+SUM(FJ12/200)*100 -> 0 | GJ12: =+SUM(FK12/44)*100 -> 0 | GK12: =+SUM(FL12/492)*100 -> 0 | GM12: =FL12+'EXTRALABORAL A '!BH11 -> 0 | GN12: =+SUM(GM12/616)*100 -> 0
A13: 9 | CK13: 1 | EO13: =+SUM(CF13:CR13) -> 1 | EP13: =+SUM(CS13:DF13) -> 0 | EQ13: =+SUM(DG13:DK13) -> 0 | ER13: =+SUM(EF13:EN13) -> 0 | ES13: =+SUM(BV13:CB13) -> 0 | ET13: =+SUM(CC13:CE13) -> 0 | EU13: =+SUM(BQ13:BT13) -> 0 | EV13: =+SUM(BH13:BK13) -> 0 | EW13: =+SUM(BM13:BO13) -> 0 | EX13: =+SUM(V13:AG13) -> 0 | EY13: =+SUM(DW13:EE13) -> 0 | EZ13: =+SUM(AH13+AI13+AJ13+BA13+BL13+BP13) -> 0 | FA13: =SUM(BD13:BG13) -> 0 | FB13: =+SUM(AN13+AQ13+AR13+AS13+AT13+AU13) -> 0 | FC13: =+SUM(AK13+AL13+AM13+AO13+AP13) -> 0 | FD13: =+SUM(AV13+AW13+AX13+AY13+BU13) -> 0 | FE13: =+SUM(AZ13+BB13+BC13) -> 0 | FF13: =+SUM(DL13+DS13+DT13+DU13+DV13) -> 0 | FG13: =+SUM(DM13:DR13) -> 0 | FH13: =+SUM(EO13:ER13) -> 1 | FI13: =+SUM(ES13:EW13) -> 0 | FJ13: =+SUM(EX13:FE13) -> 0 | FK13: =+SUM(FF13:FG13) -> 0 | FL13: =+SUM(FH13:FK13) -> 1 | FN13: =+SUM(EO13/52)*100 -> 1.9230769 | FO13: =+SUM(EP13/56)*100 -> 0 | FP13: =+SUM(EQ13/20)*100 -> 0 | FQ13: =+SUM(ER13/36)*100 -> 0 | FR13: =+SUM(ES13/28)*100 -> 0 | FS13: =+SUM(ET13/12)*100 -> 0 | FT13: =+SUM(EU13/16)*100 -> 0 | FU13: =+SUM(EV13/16)*100 -> 0 | FV13: =+SUM(EW13/12)*100 -> 0 | FW13: =+SUM(EX13/48)*100 -> 0 | FX13: =+SUM(EY13/36)*100 -> 0 | FY13: =+SUM(EZ13/24)*100 -> 0 | FZ13: =+SUM(FA13/16)*100 -> 0 | GA13: =+SUM(FB13/24)*100 -> 0 | GB13: =+SUM(FC13/20)*100 -> 0 | GC13: =+SUM(FD13/20)*100 -> 0 | GD13: =+SUM(FE13/12)*100 -> 0 | GE13: =+SUM(FF13/20)*100 -> 0 | GF13: =+SUM(FG13/24)*100 -> 0 | GG13: =+SUM(FH13/164)*100 -> 0.6097561 | GH13: =+SUM(FI13/84)*100 -> 0 | GI13: =+SUM(FJ13/200)*100 -> 0 | GJ13: =+SUM(FK13/44)*100 -> 0 | GK13: =+SUM(FL13/492)*100 -> 0.20325203 | GM13: =FL13+'EXTRALABORAL A '!BH12 -> 1 | GN13: =+SUM(GM13/616)*100 -> 0.16233766
A14: 10 | EO14: =+SUM(CF14:CR14) -> 0 | EP14: =+SUM(CS14:DF14) -> 0 | EQ14: =+SUM(DG14:DK14) -> 0 | ER14: =+SUM(EF14:EN14) -> 0 | ES14: =+SUM(BV14:CB14) -> 0 | ET14: =+SUM(CC14:CE14) -> 0 | EU14: =+SUM(BQ14:BT14) -> 0 | EV14: =+SUM(BH14:BK14) -> 0 | EW14: =+SUM(BM14:BO14) -> 0 | EX14: =+SUM(V14:AG14) -> 0 | EY14: =+SUM(DW14:EE14) -> 0 | EZ14: =+SUM(AH14+AI14+AJ14+BA14+BL14+BP14) -> 0 | FA14: =SUM(BD14:BG14) -> 0 | FB14: =+SUM(AN14+AQ14+AR14+AS14+AT14+AU14) -> 0 | FC14: =+SUM(AK14+AL14+AM14+AO14+AP14) -> 0 | FD14: =+SUM(AV14+AW14+AX14+AY14+BU14) -> 0 | FE14: =+SUM(AZ14+BB14+BC14) -> 0 | FF14: =+SUM(DL14+DS14+DT14+DU14+DV14) -> 0 | FG14: =+SUM(DM14:DR14) -> 0 | FH14: =+SUM(EO14:ER14) -> 0 | FI14: =+SUM(ES14:EW14) -> 0 | FJ14: =+SUM(EX14:FE14) -> 0 | FK14: =+SUM(FF14:FG14) -> 0 | FL14: =+SUM(FH14:FK14) -> 0 | FN14: =+SUM(EO14/52)*100 -> 0 | FO14: =+SUM(EP14/56)*100 -> 0 | FP14: =+SUM(EQ14/20)*100 -> 0 | FQ14: =+SUM(ER14/36)*100 -> 0 | FR14: =+SUM(ES14/28)*100 -> 0 | FS14: =+SUM(ET14/12)*100 -> 0 | FT14: =+SUM(EU14/16)*100 -> 0 | FU14: =+SUM(EV14/16)*100 -> 0 | FV14: =+SUM(EW14/12)*100 -> 0 | FW14: =+SUM(EX14/48)*100 -> 0 | FX14: =+SUM(EY14/36)*100 -> 0 | FY14: =+SUM(EZ14/24)*100 -> 0 | FZ14: =+SUM(FA14/16)*100 -> 0 | GA14: =+SUM(FB14/24)*100 -> 0 | GB14: =+SUM(FC14/20)*100 -> 0 | GC14: =+SUM(FD14/20)*100 -> 0 | GD14: =+SUM(FE14/12)*100 -> 0 | GE14: =+SUM(FF14/20)*100 -> 0 | GF14: =+SUM(FG14/24)*100 -> 0 | GG14: =+SUM(FH14/164)*100 -> 0 | GH14: =+SUM(FI14/84)*100 -> 0 | GI14: =+SUM(FJ14/200)*100 -> 0 | GJ14: =+SUM(FK14/44)*100 -> 0 | GK14: =+SUM(FL14/492)*100 -> 0 | GM14: =FL14+'EXTRALABORAL A '!BH13 -> 0 | GN14: =+SUM(GM14/616)*100 -> 0
A15: 11 | EO15: =+SUM(CF15:CR15) -> 0 | EP15: =+SUM(CS15:DF15) -> 0 | EQ15: =+SUM(DG15:DK15) -> 0 | ER15: =+SUM(EF15:EN15) -> 0 | ES15: =+SUM(BV15:CB15) -> 0 | ET15: =+SUM(CC15:CE15) -> 0 | EU15: =+SUM(BQ15:BT15) -> 0 | EV15: =+SUM(BH15:BK15) -> 0 | EW15: =+SUM(BM15:BO15) -> 0 | EX15: =+SUM(V15:AG15) -> 0 | EY15: =+SUM(DW15:EE15) -> 0 | EZ15: =+SUM(AH15+AI15+AJ15+BA15+BL15+BP15) -> 0 | FA15: =SUM(BD15:BG15) -> 0 | FB15: =+SUM(AN15+AQ15+AR15+AS15+AT15+AU15) -> 0 | FC15: =+SUM(AK15+AL15+AM15+AO15+AP15) -> 0 | FD15: =+SUM(AV15+AW15+AX15+AY15+BU15) -> 0 | FE15: =+SUM(AZ15+BB15+BC15) -> 0 | FF15: =+SUM(DL15+DS15+DT15+DU15+DV15) -> 0 | FG15: =+SUM(DM15:DR15) -> 0 | FH15: =+SUM(EO15:ER15) -> 0 | FI15: =+SUM(ES15:EW15) -> 0 | FJ15: =+SUM(EX15:FE15) -> 0 | FK15: =+SUM(FF15:FG15) -> 0 | FL15: =+SUM(FH15:FK15) -> 0 | FN15: =+SUM(EO15/52)*100 -> 0 | FO15: =+SUM(EP15/56)*100 -> 0 | FP15: =+SUM(EQ15/20)*100 -> 0 | FQ15: =+SUM(ER15/36)*100 -> 0 | FR15: =+SUM(ES15/28)*100 -> 0 | FS15: =+SUM(ET15/12)*100 -> 0 | FT15: =+SUM(EU15/16)*100 -> 0 | FU15: =+SUM(EV15/16)*100 -> 0 | FV15: =+SUM(EW15/12)*100 -> 0 | FW15: =+SUM(EX15/48)*100 -> 0 | FX15: =+SUM(EY15/36)*100 -> 0 | FY15: =+SUM(EZ15/24)*100 -> 0 | FZ15: =+SUM(FA15/16)*100 -> 0 | GA15: =+SUM(FB15/24)*100 -> 0 | GB15: =+SUM(FC15/20)*100 -> 0 | GC15: =+SUM(FD15/20)*100 -> 0 | GD15: =+SUM(FE15/12)*100 -> 0 | GE15: =+SUM(FF15/20)*100 -> 0 | GF15: =+SUM(FG15/24)*100 -> 0 | GG15: =+SUM(FH15/164)*100 -> 0 | GH15: =+SUM(FI15/84)*100 -> 0 | GI15: =+SUM(FJ15/200)*100 -> 0 | GJ15: =+SUM(FK15/44)*100 -> 0 | GK15: =+SUM(FL15/492)*100 -> 0 | GM15: =FL15+'EXTRALABORAL A '!BH14 -> 0 | GN15: =+SUM(GM15/616)*100 -> 0
A16: 12 | EO16: =+SUM(CF16:CR16) -> 0 | EP16: =+SUM(CS16:DF16) -> 0 | EQ16: =+SUM(DG16:DK16) -> 0 | ER16: =+SUM(EF16:EN16) -> 0 | ES16: =+SUM(BV16:CB16) -> 0 | ET16: =+SUM(CC16:CE16) -> 0 | EU16: =+SUM(BQ16:BT16) -> 0 | EV16: =+SUM(BH16:BK16) -> 0 | EW16: =+SUM(BM16:BO16) -> 0 | EX16: =+SUM(V16:AG16) -> 0 | EY16: =+SUM(DW16:EE16) -> 0 | EZ16: =+SUM(AH16+AI16+AJ16+BA16+BL16+BP16) -> 0 | FA16: =SUM(BD16:BG16) -> 0 | FB16: =+SUM(AN16+AQ16+AR16+AS16+AT16+AU16) -> 0 | FC16: =+SUM(AK16+AL16+AM16+AO16+AP16) -> 0 | FD16: =+SUM(AV16+AW16+AX16+AY16+BU16) -> 0 | FE16: =+SUM(AZ16+BB16+BC16) -> 0 | FF16: =+SUM(DL16+DS16+DT16+DU16+DV16) -> 0 | FG16: =+SUM(DM16:DR16) -> 0 | FH16: =+SUM(EO16:ER16) -> 0 | FI16: =+SUM(ES16:EW16) -> 0 | FJ16: =+SUM(EX16:FE16) -> 0 | FK16: =+SUM(FF16:FG16) -> 0 | FL16: =+SUM(FH16:FK16) -> 0 | FN16: =+SUM(EO16/52)*100 -> 0 | FO16: =+SUM(EP16/56)*100 -> 0 | FP16: =+SUM(EQ16/20)*100 -> 0 | FQ16: =+SUM(ER16/36)*100 -> 0 | FR16: =+SUM(ES16/28)*100 -> 0 | FS16: =+SUM(ET16/12)*100 -> 0 | FT16: =+SUM(EU16/16)*100 -> 0 | FU16: =+SUM(EV16/16)*100 -> 0 | FV16: =+SUM(EW16/12)*100 -> 0 | FW16: =+SUM(EX16/48)*100 -> 0 | FX16: =+SUM(EY16/36)*100 -> 0 | FY16: =+SUM(EZ16/24)*100 -> 0 | FZ16: =+SUM(FA16/16)*100 -> 0 | GA16: =+SUM(FB16/24)*100 -> 0 | GB16: =+SUM(FC16/20)*100 -> 0 | GC16: =+SUM(FD16/20)*100 -> 0 | GD16: =+SUM(FE16/12)*100 -> 0 | GE16: =+SUM(FF16/20)*100 -> 0 | GF16: =+SUM(FG16/24)*100 -> 0 | GG16: =+SUM(FH16/164)*100 -> 0 | GH16: =+SUM(FI16/84)*100 -> 0 | GI16: =+SUM(FJ16/200)*100 -> 0 | GJ16: =+SUM(FK16/44)*100 -> 0 | GK16: =+SUM(FL16/492)*100 -> 0 | GM16: =FL16+'EXTRALABORAL A '!BH15 -> 0 | GN16: =+SUM(GM16/616)*100 -> 0
A17: 13 | EO17: =+SUM(CF17:CR17) -> 0 | EP17: =+SUM(CS17:DF17) -> 0 | EQ17: =+SUM(DG17:DK17) -> 0 | ER17: =+SUM(EF17:EN17) -> 0 | ES17: =+SUM(BV17:CB17) -> 0 | ET17: =+SUM(CC17:CE17) -> 0 | EU17: =+SUM(BQ17:BT17) -> 0 | EV17: =+SUM(BH17:BK17) -> 0 | EW17: =+SUM(BM17:BO17) -> 0 | EX17: =+SUM(V17:AG17) -> 0 | EY17: =+SUM(DW17:EE17) -> 0 | EZ17: =+SUM(AH17+AI17+AJ17+BA17+BL17+BP17) -> 0 | FA17: =SUM(BD17:BG17) -> 0 | FB17: =+SUM(AN17+AQ17+AR17+AS17+AT17+AU17) -> 0 | FC17: =+SUM(AK17+AL17+AM17+AO17+AP17) -> 0 | FD17: =+SUM(AV17+AW17+AX17+AY17+BU17) -> 0 | FE17: =+SUM(AZ17+BB17+BC17) -> 0 | FF17: =+SUM(DL17+DS17+DT17+DU17+DV17) -> 0 | FG17: =+SUM(DM17:DR17) -> 0 | FH17: =+SUM(EO17:ER17) -> 0 | FI17: =+SUM(ES17:EW17) -> 0 | FJ17: =+SUM(EX17:FE17) -> 0 | FK17: =+SUM(FF17:FG17) -> 0 | FL17: =+SUM(FH17:FK17) -> 0 | FN17: =+SUM(EO17/52)*100 -> 0 | FO17: =+SUM(EP17/56)*100 -> 0 | FP17: =+SUM(EQ17/20)*100 -> 0 | FQ17: =+SUM(ER17/36)*100 -> 0 | FR17: =+SUM(ES17/28)*100 -> 0 | FS17: =+SUM(ET17/12)*100 -> 0 | FT17: =+SUM(EU17/16)*100 -> 0 | FU17: =+SUM(EV17/16)*100 -> 0 | FV17: =+SUM(EW17/12)*100 -> 0 | FW17: =+SUM(EX17/48)*100 -> 0 | FX17: =+SUM(EY17/36)*100 -> 0 | FY17: =+SUM(EZ17/24)*100 -> 0 | FZ17: =+SUM(FA17/16)*100 -> 0 | GA17: =+SUM(FB17/24)*100 -> 0 | GB17: =+SUM(FC17/20)*100 -> 0 | GC17: =+SUM(FD17/20)*100 -> 0 | GD17: =+SUM(FE17/12)*100 -> 0 | GE17: =+SUM(FF17/20)*100 -> 0 | GF17: =+SUM(FG17/24)*100 -> 0 | GG17: =+SUM(FH17/164)*100 -> 0 | GH17: =+SUM(FI17/84)*100 -> 0 | GI17: =+SUM(FJ17/200)*100 -> 0 | GJ17: =+SUM(FK17/44)*100 -> 0 | GK17: =+SUM(FL17/492)*100 -> 0 | GM17: =FL17+'EXTRALABORAL A '!BH16 -> 0 | GN17: =+SUM(GM17/616)*100 -> 0
A18: 14 | EO18: =+SUM(CF18:CR18) -> 0 | EP18: =+SUM(CS18:DF18) -> 0 | EQ18: =+SUM(DG18:DK18) -> 0 | ER18: =+SUM(EF18:EN18) -> 0 | ES18: =+SUM(BV18:CB18) -> 0 | ET18: =+SUM(CC18:CE18) -> 0 | EU18: =+SUM(BQ18:BT18) -> 0 | EV18: =+SUM(BH18:BK18) -> 0 | EW18: =+SUM(BM18:BO18) -> 0 | EX18: =+SUM(V18:AG18) -> 0 | EY18: =+SUM(DW18:EE18) -> 0 | EZ18: =+SUM(AH18+AI18+AJ18+BA18+BL18+BP18) -> 0 | FA18: =SUM(BD18:BG18) -> 0 | FB18: =+SUM(AN18+AQ18+AR18+AS18+AT18+AU18) -> 0 | FC18: =+SUM(AK18+AL18+AM18+AO18+AP18) -> 0 | FD18: =+SUM(AV18+AW18+AX18+AY18+BU18) -> 0 | FE18: =+SUM(AZ18+BB18+BC18) -> 0 | FF18: =+SUM(DL18+DS18+DT18+DU18+DV18) -> 0 | FG18: =+SUM(DM18:DR18) -> 0 | FH18: =+SUM(EO18:ER18) -> 0 | FI18: =+SUM(ES18:EW18) -> 0 | FJ18: =+SUM(EX18:FE18) -> 0 | FK18: =+SUM(FF18:FG18) -> 0 | FL18: =+SUM(FH18:FK18) -> 0 | FN18: =+SUM(EO18/52)*100 -> 0 | FO18: =+SUM(EP18/56)*100 -> 0 | FP18: =+SUM(EQ18/20)*100 -> 0 | FQ18: =+SUM(ER18/36)*100 -> 0 | FR18: =+SUM(ES18/28)*100 -> 0 | FS18: =+SUM(ET18/12)*100 -> 0 | FT18: =+SUM(EU18/16)*100 -> 0 | FU18: =+SUM(EV18/16)*100 -> 0 | FV18: =+SUM(EW18/12)*100 -> 0 | FW18: =+SUM(EX18/48)*100 -> 0 | FX18: =+SUM(EY18/36)*100 -> 0 | FY18: =+SUM(EZ18/24)*100 -> 0 | FZ18: =+SUM(FA18/16)*100 -> 0 | GA18: =+SUM(FB18/24)*100 -> 0 | GB18: =+SUM(FC18/20)*100 -> 0 | GC18: =+SUM(FD18/20)*100 -> 0 | GD18: =+SUM(FE18/12)*100 -> 0 | GE18: =+SUM(FF18/20)*100 -> 0 | GF18: =+SUM(FG18/24)*100 -> 0 | GG18: =+SUM(FH18/164)*100 -> 0 | GH18: =+SUM(FI18/84)*100 -> 0 | GI18: =+SUM(FJ18/200)*100 -> 0 | GJ18: =+SUM(FK18/44)*100 -> 0 | GK18: =+SUM(FL18/492)*100 -> 0 | GM18: =FL18+'EXTRALABORAL A '!BH17 -> 0 | GN18: =+SUM(GM18/616)*100 -> 0
A19: 15 | EO19: =+SUM(CF19:CR19) -> 0 | EP19: =+SUM(CS19:DF19) -> 0 | EQ19: =+SUM(DG19:DK19) -> 0 | ER19: =+SUM(EF19:EN19) -> 0 | ES19: =+SUM(BV19:CB19) -> 0 | ET19: =+SUM(CC19:CE19) -> 0 | EU19: =+SUM(BQ19:BT19) -> 0 | EV19: =+SUM(BH19:BK19) -> 0 | EW19: =+SUM(BM19:BO19) -> 0 | EX19: =+SUM(V19:AG19) -> 0 | EY19: =+SUM(DW19:EE19) -> 0 | EZ19: =+SUM(AH19+AI19+AJ19+BA19+BL19+BP19) -> 0 | FA19: =SUM(BD19:BG19) -> 0 | FB19: =+SUM(AN19+AQ19+AR19+AS19+AT19+AU19) -> 0 | FC19: =+SUM(AK19+AL19+AM19+AO19+AP19) -> 0 | FD19: =+SUM(AV19+AW19+AX19+AY19+BU19) -> 0 | FE19: =+SUM(AZ19+BB19+BC19) -> 0 | FF19: =+SUM(DL19+DS19+DT19+DU19+DV19) -> 0 | FG19: =+SUM(DM19:DR19) -> 0 | FH19: =+SUM(EO19:ER19) -> 0 | FI19: =+SUM(ES19:EW19) -> 0 | FJ19: =+SUM(EX19:FE19) -> 0 | FK19: =+SUM(FF19:FG19) -> 0 | FL19: =+SUM(FH19:FK19) -> 0 | FN19: =+SUM(EO19/52)*100 -> 0 | FO19: =+SUM(EP19/56)*100 -> 0 | FP19: =+SUM(EQ19/20)*100 -> 0 | FQ19: =+SUM(ER19/36)*100 -> 0 | FR19: =+SUM(ES19/28)*100 -> 0 | FS19: =+SUM(ET19/12)*100 -> 0 | FT19: =+SUM(EU19/16)*100 -> 0 | FU19: =+SUM(EV19/16)*100 -> 0 | FV19: =+SUM(EW19/12)*100 -> 0 | FW19: =+SUM(EX19/48)*100 -> 0 | FX19: =+SUM(EY19/36)*100 -> 0 | FY19: =+SUM(EZ19/24)*100 -> 0 | FZ19: =+SUM(FA19/16)*100 -> 0 | GA19: =+SUM(FB19/24)*100 -> 0 | GB19: =+SUM(FC19/20)*100 -> 0 | GC19: =+SUM(FD19/20)*100 -> 0 | GD19: =+SUM(FE19/12)*100 -> 0 | GE19: =+SUM(FF19/20)*100 -> 0 | GF19: =+SUM(FG19/24)*100 -> 0 | GG19: =+SUM(FH19/164)*100 -> 0 | GH19: =+SUM(FI19/84)*100 -> 0 | GI19: =+SUM(FJ19/200)*100 -> 0 | GJ19: =+SUM(FK19/44)*100 -> 0 | GK19: =+SUM(FL19/492)*100 -> 0 | GM19: =FL19+'EXTRALABORAL A '!BH18 -> 0 | GN19: =+SUM(GM19/616)*100 -> 0
A20: 16 | EO20: =+SUM(CF20:CR20) -> 0 | EP20: =+SUM(CS20:DF20) -> 0 | EQ20: =+SUM(DG20:DK20) -> 0 | ER20: =+SUM(EF20:EN20) -> 0 | ES20: =+SUM(BV20:CB20) -> 0 | ET20: =+SUM(CC20:CE20) -> 0 | EU20: =+SUM(BQ20:BT20) -> 0 | EV20: =+SUM(BH20:BK20) -> 0 | EW20: =+SUM(BM20:BO20) -> 0 | EX20: =+SUM(V20:AG20) -> 0 | EY20: =+SUM(DW20:EE20) -> 0 | EZ20: =+SUM(AH20+AI20+AJ20+BA20+BL20+BP20) -> 0 | FA20: =SUM(BD20:BG20) -> 0 | FB20: =+SUM(AN20+AQ20+AR20+AS20+AT20+AU20) -> 0 | FC20: =+SUM(AK20+AL20+AM20+AO20+AP20) -> 0 | FD20: =+SUM(AV20+AW20+AX20+AY20+BU20) -> 0 | FE20: =+SUM(AZ20+BB20+BC20) -> 0 | FF20: =+SUM(DL20+DS20+DT20+DU20+DV20) -> 0 | FG20: =+SUM(DM20:DR20) -> 0 | FH20: =+SUM(EO20:ER20) -> 0 | FI20: =+SUM(ES20:EW20) -> 0 | FJ20: =+SUM(EX20:FE20) -> 0 | FK20: =+SUM(FF20:FG20) -> 0 | FL20: =+SUM(FH20:FK20) -> 0 | FN20: =+SUM(EO20/52)*100 -> 0 | FO20: =+SUM(EP20/56)*100 -> 0 | FP20: =+SUM(EQ20/20)*100 -> 0 | FQ20: =+SUM(ER20/36)*100 -> 0 | FR20: =+SUM(ES20/28)*100 -> 0 | FS20: =+SUM(ET20/12)*100 -> 0 | FT20: =+SUM(EU20/16)*100 -> 0 | FU20: =+SUM(EV20/16)*100 -> 0 | FV20: =+SUM(EW20/12)*100 -> 0 | FW20: =+SUM(EX20/48)*100 -> 0 | FX20: =+SUM(EY20/36)*100 -> 0 | FY20: =+SUM(EZ20/24)*100 -> 0 | FZ20: =+SUM(FA20/16)*100 -> 0 | GA20: =+SUM(FB20/24)*100 -> 0 | GB20: =+SUM(FC20/20)*100 -> 0 | GC20: =+SUM(FD20/20)*100 -> 0 | GD20: =+SUM(FE20/12)*100 -> 0 | GE20: =+SUM(FF20/20)*100 -> 0 | GF20: =+SUM(FG20/24)*100 -> 0 | GG20: =+SUM(FH20/164)*100 -> 0 | GH20: =+SUM(FI20/84)*100 -> 0 | GI20: =+SUM(FJ20/200)*100 -> 0 | GJ20: =+SUM(FK20/44)*100 -> 0 | GK20: =+SUM(FL20/492)*100 -> 0 | GM20: =FL20+'EXTRALABORAL A '!BH19 -> 0 | GN20: =+SUM(GM20/616)*100 -> 0
A21: 17 | EO21: =+SUM(CF21:CR21) -> 0 | EP21: =+SUM(CS21:DF21) -> 0 | EQ21: =+SUM(DG21:DK21) -> 0 | ER21: =+SUM(EF21:EN21) -> 0 | ES21: =+SUM(BV21:CB21) -> 0 | ET21: =+SUM(CC21:CE21) -> 0 | EU21: =+SUM(BQ21:BT21) -> 0 | EV21: =+SUM(BH21:BK21) -> 0 | EW21: =+SUM(BM21:BO21) -> 0 | EX21: =+SUM(V21:AG21) -> 0 | EY21: =+SUM(DW21:EE21) -> 0 | EZ21: =+SUM(AH21+AI21+AJ21+BA21+BL21+BP21) -> 0 | FA21: =SUM(BD21:BG21) -> 0 | FB21: =+SUM(AN21+AQ21+AR21+AS21+AT21+AU21) -> 0 | FC21: =+SUM(AK21+AL21+AM21+AO21+AP21) -> 0 | FD21: =+SUM(AV21+AW21+AX21+AY21+BU21) -> 0 | FE21: =+SUM(AZ21+BB21+BC21) -> 0 | FF21: =+SUM(DL21+DS21+DT21+DU21+DV21) -> 0 | FG21: =+SUM(DM21:DR21) -> 0 | FH21: =+SUM(EO21:ER21) -> 0 | FI21: =+SUM(ES21:EW21) -> 0 | FJ21: =+SUM(EX21:FE21) -> 0 | FK21: =+SUM(FF21:FG21) -> 0 | FL21: =+SUM(FH21:FK21) -> 0 | FN21: =+SUM(EO21/52)*100 -> 0 | FO21: =+SUM(EP21/56)*100 -> 0 | FP21: =+SUM(EQ21/20)*100 -> 0 | FQ21: =+SUM(ER21/36)*100 -> 0 | FR21: =+SUM(ES21/28)*100 -> 0 | FS21: =+SUM(ET21/12)*100 -> 0 | FT21: =+SUM(EU21/16)*100 -> 0 | FU21: =+SUM(EV21/16)*100 -> 0 | FV21: =+SUM(EW21/12)*100 -> 0 | FW21: =+SUM(EX21/48)*100 -> 0 | FX21: =+SUM(EY21/36)*100 -> 0 | FY21: =+SUM(EZ21/24)*100 -> 0 | FZ21: =+SUM(FA21/16)*100 -> 0 | GA21: =+SUM(FB21/24)*100 -> 0 | GB21: =+SUM(FC21/20)*100 -> 0 | GC21: =+SUM(FD21/20)*100 -> 0 | GD21: =+SUM(FE21/12)*100 -> 0 | GE21: =+SUM(FF21/20)*100 -> 0 | GF21: =+SUM(FG21/24)*100 -> 0 | GG21: =+SUM(FH21/164)*100 -> 0 | GH21: =+SUM(FI21/84)*100 -> 0 | GI21: =+SUM(FJ21/200)*100 -> 0 | GJ21: =+SUM(FK21/44)*100 -> 0 | GK21: =+SUM(FL21/492)*100 -> 0 | GM21: =FL21+'EXTRALABORAL A '!BH20 -> 0 | GN21: =+SUM(GM21/616)*100 -> 0
A22: 18 | EO22: =+SUM(CF22:CR22) -> 0 | EP22: =+SUM(CS22:DF22) -> 0 | EQ22: =+SUM(DG22:DK22) -> 0 | ER22: =+SUM(EF22:EN22) -> 0 | ES22: =+SUM(BV22:CB22) -> 0 | ET22: =+SUM(CC22:CE22) -> 0 | EU22: =+SUM(BQ22:BT22) -> 0 | EV22: =+SUM(BH22:BK22) -> 0 | EW22: =+SUM(BM22:BO22) -> 0 | EX22: =+SUM(V22:AG22) -> 0 | EY22: =+SUM(DW22:EE22) -> 0 | EZ22: =+SUM(AH22+AI22+AJ22+BA22+BL22+BP22) -> 0 | FA22: =SUM(BD22:BG22) -> 0 | FB22: =+SUM(AN22+AQ22+AR22+AS22+AT22+AU22) -> 0 | FC22: =+SUM(AK22+AL22+AM22+AO22+AP22) -> 0 | FD22: =+SUM(AV22+AW22+AX22+AY22+BU22) -> 0 | FE22: =+SUM(AZ22+BB22+BC22) -> 0 | FF22: =+SUM(DL22+DS22+DT22+DU22+DV22) -> 0 | FG22: =+SUM(DM22:DR22) -> 0 | FH22: =+SUM(EO22:ER22) -> 0 | FI22: =+SUM(ES22:EW22) -> 0 | FJ22: =+SUM(EX22:FE22) -> 0 | FK22: =+SUM(FF22:FG22) -> 0 | FL22: =+SUM(FH22:FK22) -> 0 | FN22: =+SUM(EO22/52)*100 -> 0 | FO22: =+SUM(EP22/56)*100 -> 0 | FP22: =+SUM(EQ22/20)*100 -> 0 | FQ22: =+SUM(ER22/36)*100 -> 0 | FR22: =+SUM(ES22/28)*100 -> 0 | FS22: =+SUM(ET22/12)*100 -> 0 | FT22: =+SUM(EU22/16)*100 -> 0 | FU22: =+SUM(EV22/16)*100 -> 0 | FV22: =+SUM(EW22/12)*100 -> 0 | FW22: =+SUM(EX22/48)*100 -> 0 | FX22: =+SUM(EY22/36)*100 -> 0 | FY22: =+SUM(EZ22/24)*100 -> 0 | FZ22: =+SUM(FA22/16)*100 -> 0 | GA22: =+SUM(FB22/24)*100 -> 0 | GB22: =+SUM(FC22/20)*100 -> 0 | GC22: =+SUM(FD22/20)*100 -> 0 | GD22: =+SUM(FE22/12)*100 -> 0 | GE22: =+SUM(FF22/20)*100 -> 0 | GF22: =+SUM(FG22/24)*100 -> 0 | GG22: =+SUM(FH22/164)*100 -> 0 | GH22: =+SUM(FI22/84)*100 -> 0 | GI22: =+SUM(FJ22/200)*100 -> 0 | GJ22: =+SUM(FK22/44)*100 -> 0 | GK22: =+SUM(FL22/492)*100 -> 0 | GM22: =FL22+'EXTRALABORAL A '!BH21 -> 0 | GN22: =+SUM(GM22/616)*100 -> 0
A23: 19 | EO23: =+SUM(CF23:CR23) -> 0 | EP23: =+SUM(CS23:DF23) -> 0 | EQ23: =+SUM(DG23:DK23) -> 0 | ER23: =+SUM(EF23:EN23) -> 0 | ES23: =+SUM(BV23:CB23) -> 0 | ET23: =+SUM(CC23:CE23) -> 0 | EU23: =+SUM(BQ23:BT23) -> 0 | EV23: =+SUM(BH23:BK23) -> 0 | EW23: =+SUM(BM23:BO23) -> 0 | EX23: =+SUM(V23:AG23) -> 0 | EY23: =+SUM(DW23:EE23) -> 0 | EZ23: =+SUM(AH23+AI23+AJ23+BA23+BL23+BP23) -> 0 | FA23: =SUM(BD23:BG23) -> 0 | FB23: =+SUM(AN23+AQ23+AR23+AS23+AT23+AU23) -> 0 | FC23: =+SUM(AK23+AL23+AM23+AO23+AP23) -> 0 | FD23: =+SUM(AV23+AW23+AX23+AY23+BU23) -> 0 | FE23: =+SUM(AZ23+BB23+BC23) -> 0 | FF23: =+SUM(DL23+DS23+DT23+DU23+DV23) -> 0 | FG23: =+SUM(DM23:DR23) -> 0 | FH23: =+SUM(EO23:ER23) -> 0 | FI23: =+SUM(ES23:EW23) -> 0 | FJ23: =+SUM(EX23:FE23) -> 0 | FK23: =+SUM(FF23:FG23) -> 0 | FL23: =+SUM(FH23:FK23) -> 0 | FN23: =+SUM(EO23/52)*100 -> 0 | FO23: =+SUM(EP23/56)*100 -> 0 | FP23: =+SUM(EQ23/20)*100 -> 0 | FQ23: =+SUM(ER23/36)*100 -> 0 | FR23: =+SUM(ES23/28)*100 -> 0 | FS23: =+SUM(ET23/12)*100 -> 0 | FT23: =+SUM(EU23/16)*100 -> 0 | FU23: =+SUM(EV23/16)*100 -> 0 | FV23: =+SUM(EW23/12)*100 -> 0 | FW23: =+SUM(EX23/48)*100 -> 0 | FX23: =+SUM(EY23/36)*100 -> 0 | FY23: =+SUM(EZ23/24)*100 -> 0 | FZ23: =+SUM(FA23/16)*100 -> 0 | GA23: =+SUM(FB23/24)*100 -> 0 | GB23: =+SUM(FC23/20)*100 -> 0 | GC23: =+SUM(FD23/20)*100 -> 0 | GD23: =+SUM(FE23/12)*100 -> 0 | GE23: =+SUM(FF23/20)*100 -> 0 | GF23: =+SUM(FG23/24)*100 -> 0 | GG23: =+SUM(FH23/164)*100 -> 0 | GH23: =+SUM(FI23/84)*100 -> 0 | GI23: =+SUM(FJ23/200)*100 -> 0 | GJ23: =+SUM(FK23/44)*100 -> 0 | GK23: =+SUM(FL23/492)*100 -> 0 | GM23: =FL23+'EXTRALABORAL A '!BH22 -> 0 | GN23: =+SUM(GM23/616)*100 -> 0
A24: 20 | EO24: =+SUM(CF24:CR24) -> 0 | EP24: =+SUM(CS24:DF24) -> 0 | EQ24: =+SUM(DG24:DK24) -> 0 | ER24: =+SUM(EF24:EN24) -> 0 | ES24: =+SUM(BV24:CB24) -> 0 | ET24: =+SUM(CC24:CE24) -> 0 | EU24: =+SUM(BQ24:BT24) -> 0 | EV24: =+SUM(BH24:BK24) -> 0 | EW24: =+SUM(BM24:BO24) -> 0 | EX24: =+SUM(V24:AG24) -> 0 | EY24: =+SUM(DW24:EE24) -> 0 | EZ24: =+SUM(AH24+AI24+AJ24+BA24+BL24+BP24) -> 0 | FA24: =SUM(BD24:BG24) -> 0 | FB24: =+SUM(AN24+AQ24+AR24+AS24+AT24+AU24) -> 0 | FC24: =+SUM(AK24+AL24+AM24+AO24+AP24) -> 0 | FD24: =+SUM(AV24+AW24+AX24+AY24+BU24) -> 0 | FE24: =+SUM(AZ24+BB24+BC24) -> 0 | FF24: =+SUM(DL24+DS24+DT24+DU24+DV24) -> 0 | FG24: =+SUM(DM24:DR24) -> 0 | FH24: =+SUM(EO24:ER24) -> 0 | FI24: =+SUM(ES24:EW24) -> 0 | FJ24: =+SUM(EX24:FE24) -> 0 | FK24: =+SUM(FF24:FG24) -> 0 | FL24: =+SUM(FH24:FK24) -> 0 | FN24: =+SUM(EO24/52)*100 -> 0 | FO24: =+SUM(EP24/56)*100 -> 0 | FP24: =+SUM(EQ24/20)*100 -> 0 | FQ24: =+SUM(ER24/36)*100 -> 0 | FR24: =+SUM(ES24/28)*100 -> 0 | FS24: =+SUM(ET24/12)*100 -> 0 | FT24: =+SUM(EU24/16)*100 -> 0 | FU24: =+SUM(EV24/16)*100 -> 0 | FV24: =+SUM(EW24/12)*100 -> 0 | FW24: =+SUM(EX24/48)*100 -> 0 | FX24: =+SUM(EY24/36)*100 -> 0 | FY24: =+SUM(EZ24/24)*100 -> 0 | FZ24: =+SUM(FA24/16)*100 -> 0 | GA24: =+SUM(FB24/24)*100 -> 0 | GB24: =+SUM(FC24/20)*100 -> 0 | GC24: =+SUM(FD24/20)*100 -> 0 | GD24: =+SUM(FE24/12)*100 -> 0 | GE24: =+SUM(FF24/20)*100 -> 0 | GF24: =+SUM(FG24/24)*100 -> 0 | GG24: =+SUM(FH24/164)*100 -> 0 | GH24: =+SUM(FI24/84)*100 -> 0 | GI24: =+SUM(FJ24/200)*100 -> 0 | GJ24: =+SUM(FK24/44)*100 -> 0 | GK24: =+SUM(FL24/492)*100 -> 0 | GM24: =FL24+'EXTRALABORAL A '!BH23 -> 0 | GN24: =+SUM(GM24/616)*100 -> 0
A25: 21 | EO25: =+SUM(CF25:CR25) -> 0 | EP25: =+SUM(CS25:DF25) -> 0 | EQ25: =+SUM(DG25:DK25) -> 0 | ER25: =+SUM(EF25:EN25) -> 0 | ES25: =+SUM(BV25:CB25) -> 0 | ET25: =+SUM(CC25:CE25) -> 0 | EU25: =+SUM(BQ25:BT25) -> 0 | EV25: =+SUM(BH25:BK25) -> 0 | EW25: =+SUM(BM25:BO25) -> 0 | EX25: =+SUM(V25:AG25) -> 0 | EY25: =+SUM(DW25:EE25) -> 0 | EZ25: =+SUM(AH25+AI25+AJ25+BA25+BL25+BP25) -> 0 | FA25: =SUM(BD25:BG25) -> 0 | FB25: =+SUM(AN25+AQ25+AR25+AS25+AT25+AU25) -> 0 | FC25: =+SUM(AK25+AL25+AM25+AO25+AP25) -> 0 | FD25: =+SUM(AV25+AW25+AX25+AY25+BU25) -> 0 | FE25: =+SUM(AZ25+BB25+BC25) -> 0 | FF25: =+SUM(DL25+DS25+DT25+DU25+DV25) -> 0 | FG25: =+SUM(DM25:DR25) -> 0 | FH25: =+SUM(EO25:ER25) -> 0 | FI25: =+SUM(ES25:EW25) -> 0 | FJ25: =+SUM(EX25:FE25) -> 0 | FK25: =+SUM(FF25:FG25) -> 0 | FL25: =+SUM(FH25:FK25) -> 0 | FN25: =+SUM(EO25/52)*100 -> 0 | FO25: =+SUM(EP25/56)*100 -> 0 | FP25: =+SUM(EQ25/20)*100 -> 0 | FQ25: =+SUM(ER25/36)*100 -> 0 | FR25: =+SUM(ES25/28)*100 -> 0 | FS25: =+SUM(ET25/12)*100 -> 0 | FT25: =+SUM(EU25/16)*100 -> 0 | FU25: =+SUM(EV25/16)*100 -> 0 | FV25: =+SUM(EW25/12)*100 -> 0 | FW25: =+SUM(EX25/48)*100 -> 0 | FX25: =+SUM(EY25/36)*100 -> 0 | FY25: =+SUM(EZ25/24)*100 -> 0 | FZ25: =+SUM(FA25/16)*100 -> 0 | GA25: =+SUM(FB25/24)*100 -> 0 | GB25: =+SUM(FC25/20)*100 -> 0 | GC25: =+SUM(FD25/20)*100 -> 0 | GD25: =+SUM(FE25/12)*100 -> 0 | GE25: =+SUM(FF25/20)*100 -> 0 | GF25: =+SUM(FG25/24)*100 -> 0 | GG25: =+SUM(FH25/164)*100 -> 0 | GH25: =+SUM(FI25/84)*100 -> 0 | GI25: =+SUM(FJ25/200)*100 -> 0 | GJ25: =+SUM(FK25/44)*100 -> 0 | GK25: =+SUM(FL25/492)*100 -> 0 | GM25: =FL25+'EXTRALABORAL A '!BH24 -> 0 | GN25: =+SUM(GM25/616)*100 -> 0
... A31: 27 | EO31: =+SUM(CF31:CR31) -> 0 | EP31: =+SUM(CS31:DF31) -> 0 | EQ31: =+SUM(DG31:DK31) -> 0 | ER31: =+SUM(EF31:EN31) -> 0 | ES31: =+SUM(BV31:CB31) -> 0 | ET31: =+SUM(CC31:CE31) -> 0 | EU31: =+SUM(BQ31:BT31) -> 0 | EV31: =+SUM(BH31:BK31) -> 0 | EW31: =+SUM(BM31:BO31) -> 0 | EX31: =+SUM(V31:AG31) -> 0 | EY31: =+SUM(DW31:EE31) -> 0 | EZ31: =+SUM(AH31+AI31+AJ31+BA31+BL31+BP31) -> 0 | FA31: =SUM(BD31:BG31) -> 0 | FB31: =+SUM(AN31+AQ31+AR31+AS31+AT31+AU31) -> 0 | FC31: =+SUM(AK31+AL31+AM31+AO31+AP31) -> 0 | FD31: =+SUM(AV31+AW31+AX31+AY31+BU31) -> 0 | FE31: =+SUM(AZ31+BB31+BC31) -> 0 | FF31: =+SUM(DL31+DS31+DT31+DU31+DV31) -> 0 | FG31: =+SUM(DM31:DR31) -> 0 | FH31: =+SUM(EO31:ER31) -> 0 | FI31: =+SUM(ES31:EW31) -> 0 | FJ31: =+SUM(EX31:FE31) -> 0 | FK31: =+SUM(FF31:FG31) -> 0 | FL31: =+SUM(FH31:FK31) -> 0 | FN31: =+SUM(EO31/52)*100 -> 0 | FO31: =+SUM(EP31/56)*100 -> 0 | FP31: =+SUM(EQ31/20)*100 -> 0 | FQ31: =+SUM(ER31/36)*100 -> 0 | FR31: =+SUM(ES31/28)*100 -> 0 | FS31: =+SUM(ET31/12)*100 -> 0 | FT31: =+SUM(EU31/16)*100 -> 0 | FU31: =+SUM(EV31/16)*100 -> 0 | FV31: =+SUM(EW31/12)*100 -> 0 | FW31: =+SUM(EX31/48)*100 -> 0 | FX31: =+SUM(EY31/36)*100 -> 0 | FY31: =+SUM(EZ31/24)*100 -> 0 | FZ31: =+SUM(FA31/16)*100 -> 0 | GA31: =+SUM(FB31/24)*100 -> 0 | GB31: =+SUM(FC31/20)*100 -> 0 | GC31: =+SUM(FD31/20)*100 -> 0 | GD31: =+SUM(FE31/12)*100 -> 0 | GE31: =+SUM(FF31/20)*100 -> 0 | GF31: =+SUM(FG31/24)*100 -> 0 | GG31: =+SUM(FH31/164)*100 -> 0 | GH31: =+SUM(FI31/84)*100 -> 0 | GI31: =+SUM(FJ31/200)*100 -> 0 | GJ31: =+SUM(FK31/44)*100 -> 0 | GK31: =+SUM(FL31/492)*100 -> 0 | GM31: =FL31+'EXTRALABORAL A '!BH30 -> 0 | GN31: =+SUM(GM31/616)*100 -> 0
A32: 28 | EO32: =+SUM(CF32:CR32) -> 0 | EP32: =+SUM(CS32:DF32) -> 0 | EQ32: =+SUM(DG32:DK32) -> 0 | ES32: =+SUM(BV32:CB32) -> 0 | ET32: =+SUM(CC32:CE32) -> 0 | EU32: =+SUM(BQ32:BT32) -> 0 | EV32: =+SUM(BH32:BK32) -> 0 | EW32: =+SUM(BM32:BO32) -> 0 | EX32: =+SUM(V32:AG32) -> 0 | EY32: =+SUM(DW32:EE32) -> 0 | EZ32: =+SUM(AH32+AI32+AJ32+BA32+BL32+BP32) -> 0 | FA32: =SUM(BD32:BG32) -> 0 | FB32: =+SUM(AN32+AQ32+AR32+AS32+AT32+AU32) -> 0 | FC32: =+SUM(AK32+AL32+AM32+AO32+AP32) -> 0 | FD32: =+SUM(AV32+AW32+AX32+AY32+BU32) -> 0 | FE32: =+SUM(AZ32+BB32+BC32) -> 0 | FF32: =+SUM(DL32+DS32+DT32+DU32+DV32) -> 0 | FG32: =+SUM(DM32:DR32) -> 0 | FI32: =+SUM(ES32:EW32) -> 0 | FJ32: =+SUM(EX32:FE32) -> 0 | FK32: =+SUM(FF32:FG32) -> 0 | FN32: =+SUM(EO32/52)*100 -> 0 | FO32: =+SUM(EP32/56)*100 -> 0 | FP32: =+SUM(EQ32/20)*100 -> 0 | FR32: =+SUM(ES32/28)*100 -> 0 | FS32: =+SUM(ET32/12)*100 -> 0 | FT32: =+SUM(EU32/16)*100 -> 0 | FU32: =+SUM(EV32/16)*100 -> 0 | FV32: =+SUM(EW32/12)*100 -> 0 | FW32: =+SUM(EX32/48)*100 -> 0 | FX32: =+SUM(EY32/36)*100 -> 0 | FY32: =+SUM(EZ32/24)*100 -> 0 | FZ32: =+SUM(FA32/16)*100 -> 0 | GA32: =+SUM(FB32/24)*100 -> 0 | GB32: =+SUM(FC32/20)*100 -> 0 | GC32: =+SUM(FD32/20)*100 -> 0 | GD32: =+SUM(FE32/12)*100 -> 0 | GE32: =+SUM(FF32/20)*100 -> 0 | GF32: =+SUM(FG32/24)*100 -> 0 | GH32: =+SUM(FI32/84)*100 -> 0 | GI32: =+SUM(FJ32/200)*100 -> 0 | GJ32: =+SUM(FK32/44)*100 -> 0 | GK32: =+SUM(FL32/492)*100 -> 0
A33: 29 | EO33: =+SUM(CF33:CR33) -> 0 | EP33: =+SUM(CS33:DF33) -> 0 | EQ33: =+SUM(DG33:DK33) -> 0 | ES33: =+SUM(BV33:CB33) -> 0 | ET33: =+SUM(CC33:CE33) -> 0 | EU33: =+SUM(BQ33:BT33) -> 0 | EV33: =+SUM(BH33:BK33) -> 0 | EW33: =+SUM(BM33:BO33) -> 0 | EX33: =+SUM(V33:AG33) -> 0 | EZ33: =+SUM(AH33+AI33+AJ33+BA33+BL33+BP33) -> 0 | FA33: =SUM(BD33:BG33) -> 0 | FB33: =+SUM(AN33+AQ33+AR33+AS33+AT33+AU33) -> 0 | FC33: =+SUM(AK33+AL33+AM33+AO33+AP33) -> 0 | FD33: =+SUM(AV33+AW33+AX33+AY33+BU33) -> 0 | FE33: =+SUM(AZ33+BB33+BC33) -> 0 | FF33: =+SUM(DL33+DS33+DT33+DU33+DV33) -> 0 | FG33: =+SUM(DM33:DR33) -> 0 | FI33: =+SUM(ES33:EW33) -> 0 | FK33: =+SUM(FF33:FG33) -> 0 | FN33: =+SUM(EO33/52)*100 -> 0 | FO33: =+SUM(EP33/56)*100 -> 0 | FP33: =+SUM(EQ33/20)*100 -> 0 | FR33: =+SUM(ES33/28)*100 -> 0 | FS33: =+SUM(ET33/12)*100 -> 0 | FT33: =+SUM(EU33/16)*100 -> 0 | FU33: =+SUM(EV33/16)*100 -> 0 | FV33: =+SUM(EW33/12)*100 -> 0 | FW33: =+SUM(EX33/48)*100 -> 0 | FY33: =+SUM(EZ33/24)*100 -> 0 | FZ33: =+SUM(FA33/16)*100 -> 0 | GA33: =+SUM(FB33/24)*100 -> 0 | GB33: =+SUM(FC33/20)*100 -> 0 | GC33: =+SUM(FD33/20)*100 -> 0 | GD33: =+SUM(FE33/12)*100 -> 0 | GE33: =+SUM(FF33/20)*100 -> 0 | GF33: =+SUM(FG33/24)*100 -> 0 | GH33: =+SUM(FI33/84)*100 -> 0 | GJ33: =+SUM(FK33/44)*100 -> 0
A34: 30 | EO34: =+SUM(CF34:CR34) -> 0 | EP34: =+SUM(CS34:DF34) -> 0 | EQ34: =+SUM(DG34:DK34) -> 0 | ES34: =+SUM(BV34:CB34) -> 0 | ET34: =+SUM(CC34:CE34) -> 0 | EU34: =+SUM(BQ34:BT34) -> 0 | EV34: =+SUM(BH34:BK34) -> 0 | EW34: =+SUM(BM34:BO34) -> 0 | EX34: =+SUM(V34:AG34) -> 0 | EZ34: =+SUM(AH34+AI34+AJ34+BA34+BL34+BP34) -> 0 | FA34: =SUM(BD34:BG34) -> 0 | FB34: =+SUM(AN34+AQ34+AR34+AS34+AT34+AU34) -> 0 | FC34: =+SUM(AK34+AL34+AM34+AO34+AP34) -> 0 | FD34: =+SUM(AV34+AW34+AX34+AY34+BU34) -> 0 | FE34: =+SUM(AZ34+BB34+BC34) -> 0 | FF34: =+SUM(DL34+DS34+DT34+DU34+DV34) -> 0 | FG34: =+SUM(DM34:DR34) -> 0 | FI34: =+SUM(ES34:EW34) -> 0 | FK34: =+SUM(FF34:FG34) -> 0 | FN34: =+SUM(EO34/52)*100 -> 0 | FO34: =+SUM(EP34/56)*100 -> 0 | FP34: =+SUM(EQ34/20)*100 -> 0 | FR34: =+SUM(ES34/28)*100 -> 0 | FS34: =+SUM(ET34/12)*100 -> 0 | FT34: =+SUM(EU34/16)*100 -> 0 | FU34: =+SUM(EV34/16)*100 -> 0 | FV34: =+SUM(EW34/12)*100 -> 0 | FW34: =+SUM(EX34/48)*100 -> 0 | FY34: =+SUM(EZ34/24)*100 -> 0 | FZ34: =+SUM(FA34/16)*100 -> 0 | GA34: =+SUM(FB34/24)*100 -> 0 | GB34: =+SUM(FC34/20)*100 -> 0 | GC34: =+SUM(FD34/20)*100 -> 0 | GD34: =+SUM(FE34/12)*100 -> 0 | GE34: =+SUM(FF34/20)*100 -> 0 | GF34: =+SUM(FG34/24)*100 -> 0 | GH34: =+SUM(FI34/84)*100 -> 0 | GJ34: =+SUM(FK34/44)*100 -> 0
A35: 31 | EO35: =+SUM(CF35:CR35) -> 0 | EP35: =+SUM(CS35:DF35) -> 0 | EQ35: =+SUM(DG35:DK35) -> 0 | ES35: =+SUM(BV35:CB35) -> 0 | ET35: =+SUM(CC35:CE35) -> 0 | EU35: =+SUM(BQ35:BT35) -> 0 | EV35: =+SUM(BH35:BK35) -> 0 | EW35: =+SUM(BM35:BO35) -> 0 | EX35: =+SUM(V35:AG35) -> 0 | FA35: =SUM(BD35:BG35) -> 0 | FB35: =+SUM(AN35+AQ35+AR35+AS35+AT35+AU35) -> 0 | FC35: =+SUM(AK35+AL35+AM35+AO35+AP35) -> 0 | FD35: =+SUM(AV35+AW35+AX35+AY35+BU35) -> 0 | FE35: =+SUM(AZ35+BB35+BC35) -> 0 | FF35: =+SUM(DL35+DS35+DT35+DU35+DV35) -> 0 | FG35: =+SUM(DM35:DR35) -> 0 | FI35: =+SUM(ES35:EW35) -> 0 | FK35: =+SUM(FF35:FG35) -> 0 | FN35: =+SUM(EO35/52)*100 -> 0 | FO35: =+SUM(EP35/56)*100 -> 0 | FP35: =+SUM(EQ35/20)*100 -> 0 | FR35: =+SUM(ES35/28)*100 -> 0 | FS35: =+SUM(ET35/12)*100 -> 0 | FT35: =+SUM(EU35/16)*100 -> 0 | FU35: =+SUM(EV35/16)*100 -> 0 | FV35: =+SUM(EW35/12)*100 -> 0 | FW35: =+SUM(EX35/48)*100 -> 0 | FZ35: =+SUM(FA35/16)*100 -> 0 | GA35: =+SUM(FB35/24)*100 -> 0 | GB35: =+SUM(FC35/20)*100 -> 0 | GC35: =+SUM(FD35/20)*100 -> 0 | GD35: =+SUM(FE35/12)*100 -> 0 | GE35: =+SUM(FF35/20)*100 -> 0 | GF35: =+SUM(FG35/24)*100 -> 0 | GH35: =+SUM(FI35/84)*100 -> 0 | GJ35: =+SUM(FK35/44)*100 -> 0
A36: 32 | EO36: =+SUM(CF36:CR36) -> 0 | EP36: =+SUM(CS36:DF36) -> 0 | EQ36: =+SUM(DG36:DK36) -> 0 | ES36: =+SUM(BV36:CB36) -> 0 | ET36: =+SUM(CC36:CE36) -> 0 | EU36: =+SUM(BQ36:BT36) -> 0 | EV36: =+SUM(BH36:BK36) -> 0 | EW36: =+SUM(BM36:BO36) -> 0 | EX36: =+SUM(V36:AG36) -> 0 | FA36: =SUM(BD36:BG36) -> 0 | FB36: =+SUM(AN36+AQ36+AR36+AS36+AT36+AU36) -> 0 | FC36: =+SUM(AK36+AL36+AM36+AO36+AP36) -> 0 | FD36: =+SUM(AV36+AW36+AX36+AY36+BU36) -> 0 | FE36: =+SUM(AZ36+BB36+BC36) -> 0 | FF36: =+SUM(DL36+DS36+DT36+DU36+DV36) -> 0 | FG36: =+SUM(DM36:DR36) -> 0 | FI36: =+SUM(ES36:EW36) -> 0 | FK36: =+SUM(FF36:FG36) -> 0 | FN36: =+SUM(EO36/52)*100 -> 0 | FO36: =+SUM(EP36/56)*100 -> 0 | FP36: =+SUM(EQ36/20)*100 -> 0 | FR36: =+SUM(ES36/28)*100 -> 0 | FS36: =+SUM(ET36/12)*100 -> 0 | FT36: =+SUM(EU36/16)*100 -> 0 | FU36: =+SUM(EV36/16)*100 -> 0 | FV36: =+SUM(EW36/12)*100 -> 0 | FW36: =+SUM(EX36/48)*100 -> 0 | FZ36: =+SUM(FA36/16)*100 -> 0 | GA36: =+SUM(FB36/24)*100 -> 0 | GB36: =+SUM(FC36/20)*100 -> 0 | GC36: =+SUM(FD36/20)*100 -> 0 | GD36: =+SUM(FE36/12)*100 -> 0 | GE36: =+SUM(FF36/20)*100 -> 0 | GF36: =+SUM(FG36/24)*100 -> 0 | GH36: =+SUM(FI36/84)*100 -> 0 | GJ36: =+SUM(FK36/44)*100 -> 0
A37: 33 | EO37: =+SUM(CF37:CR37) -> 0 | EP37: =+SUM(CS37:DF37) -> 0 | EQ37: =+SUM(DG37:DK37) -> 0 | ES37: =+SUM(BV37:CB37) -> 0 | ET37: =+SUM(CC37:CE37) -> 0 | EU37: =+SUM(BQ37:BT37) -> 0 | EV37: =+SUM(BH37:BK37) -> 0 | EW37: =+SUM(BM37:BO37) -> 0 | EX37: =+SUM(V37:AG37) -> 0 | FA37: =SUM(BD37:BG37) -> 0 | FB37: =+SUM(AN37+AQ37+AR37+AS37+AT37+AU37) -> 0 | FC37: =+SUM(AK37+AL37+AM37+AO37+AP37) -> 0 | FD37: =+SUM(AV37+AW37+AX37+AY37+BU37) -> 0 | FE37: =+SUM(AZ37+BB37+BC37) -> 0 | FF37: =+SUM(DL37+DS37+DT37+DU37+DV37) -> 0 | FG37: =+SUM(DM37:DR37) -> 0 | FI37: =+SUM(ES37:EW37) -> 0 | FK37: =+SUM(FF37:FG37) -> 0 | FN37: =+SUM(EO37/52)*100 -> 0 | FO37: =+SUM(EP37/56)*100 -> 0 | FP37: =+SUM(EQ37/20)*100 -> 0 | FR37: =+SUM(ES37/28)*100 -> 0 | FS37: =+SUM(ET37/12)*100 -> 0 | FT37: =+SUM(EU37/16)*100 -> 0 | FU37: =+SUM(EV37/16)*100 -> 0 | FV37: =+SUM(EW37/12)*100 -> 0 | FW37: =+SUM(EX37/48)*100 -> 0 | FZ37: =+SUM(FA37/16)*100 -> 0 | GA37: =+SUM(FB37/24)*100 -> 0 | GB37: =+SUM(FC37/20)*100 -> 0 | GC37: =+SUM(FD37/20)*100 -> 0 | GD37: =+SUM(FE37/12)*100 -> 0 | GE37: =+SUM(FF37/20)*100 -> 0 | GF37: =+SUM(FG37/24)*100 -> 0 | GH37: =+SUM(FI37/84)*100 -> 0 | GJ37: =+SUM(FK37/44)*100 -> 0
A38: 34 | EO38: =+SUM(CF38:CR38) -> 0 | EP38: =+SUM(CS38:DF38) -> 0 | EQ38: =+SUM(DG38:DK38) -> 0 | ES38: =+SUM(BV38:CB38) -> 0 | ET38: =+SUM(CC38:CE38) -> 0 | EU38: =+SUM(BQ38:BT38) -> 0 | EV38: =+SUM(BH38:BK38) -> 0 | EW38: =+SUM(BM38:BO38) -> 0 | EX38: =+SUM(V38:AG38) -> 0 | FA38: =SUM(BD38:BG38) -> 0 | FB38: =+SUM(AN38+AQ38+AR38+AS38+AT38+AU38) -> 0 | FC38: =+SUM(AK38+AL38+AM38+AO38+AP38) -> 0 | FD38: =+SUM(AV38+AW38+AX38+AY38+BU38) -> 0 | FE38: =+SUM(AZ38+BB38+BC38) -> 0 | FF38: =+SUM(DL38+DS38+DT38+DU38+DV38) -> 0 | FG38: =+SUM(DM38:DR38) -> 0 | FI38: =+SUM(ES38:EW38) -> 0 | FK38: =+SUM(FF38:FG38) -> 0 | FN38: =+SUM(EO38/52)*100 -> 0 | FO38: =+SUM(EP38/56)*100 -> 0 | FP38: =+SUM(EQ38/20)*100 -> 0 | FR38: =+SUM(ES38/28)*100 -> 0 | FS38: =+SUM(ET38/12)*100 -> 0 | FT38: =+SUM(EU38/16)*100 -> 0 | FU38: =+SUM(EV38/16)*100 -> 0 | FV38: =+SUM(EW38/12)*100 -> 0 | FW38: =+SUM(EX38/48)*100 -> 0 | FZ38: =+SUM(FA38/16)*100 -> 0 | GA38: =+SUM(FB38/24)*100 -> 0 | GB38: =+SUM(FC38/20)*100 -> 0 | GC38: =+SUM(FD38/20)*100 -> 0 | GD38: =+SUM(FE38/12)*100 -> 0 | GE38: =+SUM(FF38/20)*100 -> 0 | GF38: =+SUM(FG38/24)*100 -> 0 | GH38: =+SUM(FI38/84)*100 -> 0 | GJ38: =+SUM(FK38/44)*100 -> 0
A39: 35 | EO39: =+SUM(CF39:CR39) -> 0 | EP39: =+SUM(CS39:DF39) -> 0 | EQ39: =+SUM(DG39:DK39) -> 0 | ES39: =+SUM(BV39:CB39) -> 0 | ET39: =+SUM(CC39:CE39) -> 0 | EU39: =+SUM(BQ39:BT39) -> 0 | EV39: =+SUM(BH39:BK39) -> 0 | EW39: =+SUM(BM39:BO39) -> 0 | EX39: =+SUM(V39:AG39) -> 0 | FA39: =SUM(BD39:BG39) -> 0 | FB39: =+SUM(AN39+AQ39+AR39+AS39+AT39+AU39) -> 0 | FC39: =+SUM(AK39+AL39+AM39+AO39+AP39) -> 0 | FD39: =+SUM(AV39+AW39+AX39+AY39+BU39) -> 0 | FE39: =+SUM(AZ39+BB39+BC39) -> 0 | FF39: =+SUM(DL39+DS39+DT39+DU39+DV39) -> 0 | FG39: =+SUM(DM39:DR39) -> 0 | FI39: =+SUM(ES39:EW39) -> 0 | FK39: =+SUM(FF39:FG39) -> 0 | FN39: =+SUM(EO39/52)*100 -> 0 | FO39: =+SUM(EP39/56)*100 -> 0 | FP39: =+SUM(EQ39/20)*100 -> 0 | FR39: =+SUM(ES39/28)*100 -> 0 | FS39: =+SUM(ET39/12)*100 -> 0 | FT39: =+SUM(EU39/16)*100 -> 0 | FU39: =+SUM(EV39/16)*100 -> 0 | FV39: =+SUM(EW39/12)*100 -> 0 | FW39: =+SUM(EX39/48)*100 -> 0 | FZ39: =+SUM(FA39/16)*100 -> 0 | GA39: =+SUM(FB39/24)*100 -> 0 | GB39: =+SUM(FC39/20)*100 -> 0 | GC39: =+SUM(FD39/20)*100 -> 0 | GD39: =+SUM(FE39/12)*100 -> 0 | GE39: =+SUM(FF39/20)*100 -> 0 | GF39: =+SUM(FG39/24)*100 -> 0 | GH39: =+SUM(FI39/84)*100 -> 0 | GJ39: =+SUM(FK39/44)*100 -> 0
A40: 36 | EO40: =+SUM(CF40:CR40) -> 0 | EP40: =+SUM(CS40:DF40) -> 0 | EQ40: =+SUM(DG40:DK40) -> 0 | ES40: =+SUM(BV40:CB40) -> 0 | ET40: =+SUM(CC40:CE40) -> 0 | EU40: =+SUM(BQ40:BT40) -> 0 | EV40: =+SUM(BH40:BK40) -> 0 | EW40: =+SUM(BM40:BO40) -> 0 | FA40: =SUM(BD40:BG40) -> 0 | FB40: =+SUM(AN40+AQ40+AR40+AS40+AT40+AU40) -> 0 | FC40: =+SUM(AK40+AL40+AM40+AO40+AP40) -> 0 | FD40: =+SUM(AV40+AW40+AX40+AY40+BU40) -> 0 | FE40: =+SUM(AZ40+BB40+BC40) -> 0 | FF40: =+SUM(DL40+DS40+DT40+DU40+DV40) -> 0 | FG40: =+SUM(DM40:DR40) -> 0 | FI40: =+SUM(ES40:EW40) -> 0 | FK40: =+SUM(FF40:FG40) -> 0 | FN40: =+SUM(EO40/52)*100 -> 0 | FO40: =+SUM(EP40/56)*100 -> 0 | FP40: =+SUM(EQ40/20)*100 -> 0 | FR40: =+SUM(ES40/28)*100 -> 0 | FS40: =+SUM(ET40/12)*100 -> 0 | FT40: =+SUM(EU40/16)*100 -> 0 | FU40: =+SUM(EV40/16)*100 -> 0 | FV40: =+SUM(EW40/12)*100 -> 0 | FZ40: =+SUM(FA40/16)*100 -> 0 | GA40: =+SUM(FB40/24)*100 -> 0 | GB40: =+SUM(FC40/20)*100 -> 0 | GC40: =+SUM(FD40/20)*100 -> 0 | GD40: =+SUM(FE40/12)*100 -> 0 | GE40: =+SUM(FF40/20)*100 -> 0 | GF40: =+SUM(FG40/24)*100 -> 0 | GH40: =+SUM(FI40/84)*100 -> 0 | GJ40: =+SUM(FK40/44)*100 -> 0
A41: 37 | EO41: =+SUM(CF41:CR41) -> 0 | EP41: =+SUM(CS41:DF41) -> 0 | EQ41: =+SUM(DG41:DK41) -> 0 | ES41: =+SUM(BV41:CB41) -> 0 | FC41: =+SUM(AK41+AL41+AM41+AO41+AP41) -> 0 | FF41: =+SUM(DL41+DS41+DT41+DU41+DV41) -> 0 | FN41: =+SUM(EO41/52)*100 -> 0 | FO41: =+SUM(EP41/56)*100 -> 0 | FP41: =+SUM(EQ41/20)*100 -> 0 | FR41: =+SUM(ES41/28)*100 -> 0 | GB41: =+SUM(FC41/20)*100 -> 0 | GE41: =+SUM(FF41/20)*100 -> 0
A42: 38 | EO42: =+SUM(CF42:CR42) -> 0 | EP42: =+SUM(CS42:DF42) -> 0 | EQ42: =+SUM(DG42:DK42) -> 0 | ES42: =+SUM(BV42:CB42) -> 0 | FC42: =+SUM(AK42+AL42+AM42+AO42+AP42) -> 0 | FF42: =+SUM(DL42+DS42+DT42+DU42+DV42) -> 0 | FN42: =+SUM(EO42/52)*100 -> 0 | FO42: =+SUM(EP42/56)*100 -> 0 | FP42: =+SUM(EQ42/20)*100 -> 0 | FR42: =+SUM(ES42/28)*100 -> 0 | GB42: =+SUM(FC42/20)*100 -> 0 | GE42: =+SUM(FF42/20)*100 -> 0
A43: 39 | EO43: =+SUM(CF43:CR43) -> 0 | EP43: =+SUM(CS43:DF43) -> 0 | EQ43: =+SUM(DG43:DK43) -> 0 | ES43: =+SUM(BV43:CB43) -> 0 | FC43: =+SUM(AK43+AL43+AM43+AO43+AP43) -> 0 | FF43: =+SUM(DL43+DS43+DT43+DU43+DV43) -> 0 | FN43: =+SUM(EO43/52)*100 -> 0 | FO43: =+SUM(EP43/56)*100 -> 0 | FP43: =+SUM(EQ43/20)*100 -> 0 | FR43: =+SUM(ES43/28)*100 -> 0 | GB43: =+SUM(FC43/20)*100 -> 0 | GE43: =+SUM(FF43/20)*100 -> 0
A44: 40 | EO44: =+SUM(CF44:CR44) -> 0 | EP44: =+SUM(CS44:DF44) -> 0 | EQ44: =+SUM(DG44:DK44) -> 0 | ES44: =+SUM(BV44:CB44) -> 0 | FC44: =+SUM(AK44+AL44+AM44+AO44+AP44) -> 0 | FF44: =+SUM(DL44+DS44+DT44+DU44+DV44) -> 0 | FN44: =+SUM(EO44/52)*100 -> 0 | FO44: =+SUM(EP44/56)*100 -> 0 | FP44: =+SUM(EQ44/20)*100 -> 0 | FR44: =+SUM(ES44/28)*100 -> 0 | GB44: =+SUM(FC44/20)*100 -> 0 | GE44: =+SUM(FF44/20)*100 -> 0
A45: 41 | EO45: =+SUM(CF45:CR45) -> 0 | EP45: =+SUM(CS45:DF45) -> 0 | EQ45: =+SUM(DG45:DK45) -> 0 | ES45: =+SUM(BV45:CB45) -> 0 | FC45: =+SUM(AK45+AL45+AM45+AO45+AP45) -> 0 | FF45: =+SUM(DL45+DS45+DT45+DU45+DV45) -> 0 | FN45: =+SUM(EO45/52)*100 -> 0 | FO45: =+SUM(EP45/56)*100 -> 0 | FP45: =+SUM(EQ45/20)*100 -> 0 | FR45: =+SUM(ES45/28)*100 -> 0 | GB45: =+SUM(FC45/20)*100 -> 0 | GE45: =+SUM(FF45/20)*100 -> 0
...

Sheet EXTRALABORAL A 
A1: DATOS GENERALES | V1: PREGUNTAS | BA1: TOTAL DIMENSIONES | BH1: TOTAL | BJ1: TOTAL DIMENSIONES | BQ1: PUNTAJE TOTAL DEL CUESTIONARIO FRPE
A3: ITEM | B3: Nombre | C3: Identificacion | D3: Sexo | E3: Año Nacimiento | F3: Estado Civil | G3: Ultimo nivel de estudio | H3: Ocupacion/Profesion | I3: Lugar de Residencia | J3: Estrato | K3: Tipo de Vivienda | L3: Numero de personas a cargo | M3: Lugar donde trabaja actualmente | N3: Tiempo de trabajo en la empresa | O3: Cargo actual | P3: Selecciones el tipo de cargo | Q3: Hace cuantos años que desempeña el cargo u oficio en la empresa | R3: Nombre del area o seccion de la empresa en el que trabaja | S3: Tipo de contrato | T3: Horas diarias de trabajo al dia | U3: Tipo de salario que recibe | V3: 1 | W3: 2 | X3: 3 | Y3: 4 | Z3: 5 | AA3: 6 | AB3: 7 | AC3: 8 | AD3: 9 | AE3: 10 | AF3: 11 | AG3: 12 | AH3: 13 | AI3: 14 | AJ3: 15 | AK3: 16 | AL3: 17 | AM3: 18 | AN3: 19 | AO3: 20 | AP3: 21 | AQ3: 22 | AR3: 23 | AS3: 24 | AT3: 25 | AU3: 26 | AV3: 27 | AW3: 28 | AX3: 29 | AY3: 30 | AZ3: 31 | BA3: Tiempo Fuera del Trabajo | BB3: Relaciones Familiares | BC3: Comunicación y relaciones interpersonales | BD3: Situacion Economica del Grupo Familiar | BE3: Caracteristicas de la Vivienda y de su entorno | BF3: Influencia del entorno extralaboral sobre el trabajo | BG3: Desplazamiento vivienda - Trabajo - Vivienda | BJ3: Tiempo Fuera del Trabajo | BK3: Relaciones Familiares | BL3: Comunicación y relaciones interpersonales | BM3: Situacion Economica del Grupo Familiar | BN3: Caracteristicas de la Vivienda y de su entorno | BO3: Influencia del Entorno extralaboral sobre el trabajo | BP3: Desplazamiento vivienda - Trabajo - Vivienda
A4: 1 | B4: ='INTRA LABORAL A'!B5 -> Adriana Katheribe Farfan | C4: ='INTRA LABORAL A'!C5 -> 1075274331 | D4: ='INTRA LABORAL A'!D5 -> f | E4: ='INTRA LABORAL A'!E5 -> 1993 | F4: ='INTRA LABORAL A'!F5 -> Casado | G4: ='INTRA LABORAL A'!G5 -> Post-grado incompleto | H4: ='INTRA LABORAL A'!H5 -> Ingeniero industrial | I4: ='INTRA LABORAL A'!I5 -> Neiva | ... U4: ='INTRA LABORAL A'!U5 -> Fijo | V4: 1 | W4: 0 | X4: 3 | Y4: 1 | Z4: 1 | AA4: 1 | AB4: 1 | AC4: 2 | AD4: 1 | AE4: 1 | AF4: 0 | AG4: 0 | AH4: 0 | AI4: 2 | AJ4: 2 | AK4: 2 | AL4: 2 | AM4: 0 | AN4: 0 | AO4: 0 | AP4: 0 | AQ4: 0 | AR4: 0 | AS4: 1 | AT4: 0 | AU4: 2 | AV4: 0 | AW4: 1 | AX4: 0 | AY4: 2 | AZ4: 1 | BA4: =SUM(AI4:AL4) -> 8 | BB4: =SUM(AQ4+AT4+AV4) -> 0 | BC4: =SUM(AM4+AN4+AO4+AP4+AR4) -> 0 | BD4: =SUM(AX4+AY4+AZ4) -> 3 | BE4: =SUM(Z4:AH4) -> 7 | BF4: =SUM(AS4+AU4+AW4) -> 4 | BG4: =SUM(V4:Y4) -> 5 | BH4: =SUM(BA4:BG4) -> 27 | BJ4: =SUM(BA4/16)*100 -> 50 | BK4: =SUM(BB4/12)*100 -> 0 | BL4: =SUM(BC4/20)*100 -> 0 | BM4: =SUM(BD4/12)*100 -> 25 | BN4: =SUM(BE4/36)*100 -> 19.444444 | BO4: =SUM(BF4/12)*100 -> 33.333333 | BP4: =SUM(BG4/16)*100 -> 31.25 | BQ4: =SUM(BH4/124)*100 -> 21.774194
